<sdf version='1.9'>
  <model name='Hello Robot Stretch 2'>
    <link name='base_link'>
      <inertial>
        <pose>-0.08328307830857613 0.05347682719568752 0.4423727373158793 0 0 0</pose>
        <mass>2.0456725833447211</mass>
        <inertia>
          <ixx>0.44473233360984599</ixx>
          <ixy>-0.0026084945645250121</ixy>
          <ixz>-0.025671815804644081</ixz>
          <iyy>0.44046498407791129</iyy>
          <iyz>-0.045187940045957282</iyz>
          <izz>0.016383573164105731</izz>
        </inertia>
      </inertial>
      <collision name='base_link_collision'>
        <pose>0 0 0 0 0 0</pose>
        <geometry>
          <mesh>
            <scale>1 1 1</scale>
            <uri>meshes/base_link.STL</uri>
          </mesh>
        </geometry>
      </collision>
      <collision name='base_link_fixed_joint_lump__caster_link_collision_1'>
        <pose>-0.245 0 0.032 -1.570796326794896 0 0</pose>
        <geometry>
          <sphere>
            <radius>0.032000000000000001</radius>
          </sphere>
        </geometry>
      </collision>
      <collision name='base_link_fixed_joint_lump__link_aruco_left_base_collision_2'>
        <pose>-0.00500000000000014 0.1304972 0.1597482 0 0 -1.5707963267949</pose>
        <geometry>
          <mesh>
            <scale>1 1 1</scale>
            <uri>meshes/link_aruco_left_base.STL</uri>
          </mesh>
        </geometry>
      </collision>
      <collision name='base_link_fixed_joint_lump__link_aruco_right_base_collision_3'>
        <pose>-0.00500000000000014 -0.1304972 0.1597482 0 0 -1.5707963267949</pose>
        <geometry>
          <mesh>
            <scale>1 1 1</scale>
            <uri>meshes/link_aruco_right_base.STL</uri>
          </mesh>
        </geometry>
      </collision>
      <collision name='base_link_fixed_joint_lump__laser_collision_4'>
        <pose>0.000502800000000914 0 0.1664 0 0 -3.14159265358979</pose>
        <geometry>
          <mesh>
            <scale>1 1 1</scale>
            <uri>meshes/laser.STL</uri>
          </mesh>
        </geometry>
      </collision>
      <collision name='base_link_fixed_joint_lump__link_mast_collision_5'>
        <pose>-0.07000000000000001 0.134999999999998 0.0284000000000001 1.5707963267949 8.673617379884035e-19 0.009253189265712452</pose>
        <geometry>
          <mesh>
            <scale>1 1 1</scale>
            <uri>meshes/link_mast.STL</uri>
          </mesh>
        </geometry>
      </collision>
      <collision name='base_link_fixed_joint_lump__link_head_collision_6'>
        <pose>-0.06999999999999997 0.1349999999999933 1.3584 1.101929786767748e-05 6.829364997144519e-08 -1.57083946432383</pose>
        <geometry>
          <mesh>
            <scale>1 1 1</scale>
            <uri>meshes/link_head.STL</uri>
          </mesh>
        </geometry>
      </collision>
      <collision name='base_link_fixed_joint_lump__respeaker_base_collision_7'>
        <pose>-0.06996100322803465 0.1319645029192444 1.39832 6.299472870381203e-13 -6.333935162588983e-13 -3.132339464324081</pose>
        <geometry>
          <mesh>
            <scale>1 1 1</scale>
            <uri>meshes/link_respeaker.STL</uri>
          </mesh>
        </geometry>
      </collision>
      <visual name='base_link_visual'>
        <pose>0 0 0 0 0 0</pose>
        <geometry>
          <mesh>
            <scale>1 1 1</scale>
            <uri>meshes/base_link.STL</uri>
          </mesh>
        </geometry>
        <material>
          <ambient>0.473531 0.479320 0.485150 1</ambient>
          <diffuse>0.473531 0.479320 0.485150 1</diffuse>
          <specular>0.473531 0.479320 0.485150 1</specular>
        </material>
      </visual>
      <visual name='base_link_fixed_joint_lump__caster_link_visual_1'>
        <pose>-0.245 0 0.032 -1.570796326794896 0 0</pose>
        <geometry>
          <mesh>
            <scale>1 1 1</scale>
            <uri>meshes/omni_wheel_m.STL</uri>
          </mesh>
        </geometry>
        <material>
          <ambient>0.8 0.001381 0 1</ambient>
          <diffuse>0.8 0.001381 0 1</diffuse>
          <specular>0.8 0.001381 0 1</specular>
        </material>
      </visual>
      <visual name='base_link_fixed_joint_lump__link_aruco_left_base_visual_2'>
        <pose>-0.00500000000000014 0.1304972 0.1597482 0 0 -1.5707963267949</pose>
        <geometry>
          <mesh>
            <scale>1 1 1</scale>
            <uri>meshes/link_aruco_left_base.STL</uri>
          </mesh>
        </geometry>
        <material>
          <ambient>1 1 1 1</ambient>
          <diffuse>1 1 1 1</diffuse>
          <specular>1 1 1 1</specular>
        </material>
      </visual>
      <visual name='base_link_fixed_joint_lump__link_aruco_right_base_visual_3'>
        <pose>-0.00500000000000014 -0.1304972 0.1597482 0 0 -1.5707963267949</pose>
        <geometry>
          <mesh>
            <scale>1 1 1</scale>
            <uri>meshes/link_aruco_right_base.STL</uri>
          </mesh>
        </geometry>
        <material>
          <ambient>1 1 1 1</ambient>
          <diffuse>1 1 1 1</diffuse>
          <specular>1 1 1 1</specular>
        </material>
      </visual>
      <visual name='base_link_fixed_joint_lump__laser_visual_4'>
        <pose>0.000502800000000914 0 0.1664 0 0 -3.14159265358979</pose>
        <geometry>
          <mesh>
            <scale>1 1 1</scale>
            <uri>meshes/laser.STL</uri>
          </mesh>
        </geometry>
        <material>
          <ambient>0 0 0 1</ambient>
          <diffuse>0 0 0 1</diffuse>
          <specular>0 0 0 1</specular>
        </material>
      </visual>
      <visual name='base_link_fixed_joint_lump__link_mast_visual_5'>
        <pose>-0.07000000000000001 0.134999999999998 0.0284000000000001 1.5707963267949 8.673617379884035e-19 0.009253189265712452</pose>
        <geometry>
          <mesh>
            <scale>1 1 1</scale>
            <uri>meshes/link_mast.STL</uri>
          </mesh>
        </geometry>
        <material>
          <ambient>0 0 0 1</ambient>
          <diffuse>0 0 0 1</diffuse>
          <specular>0 0 0 1</specular>
        </material>
      </visual>
      <visual name='base_link_fixed_joint_lump__link_head_visual_6'>
        <pose>-0.06999999999999997 0.1349999999999933 1.3584 1.101929786767748e-05 6.829364997144519e-08 -1.57083946432383</pose>
        <geometry>
          <mesh>
            <scale>1 1 1</scale>
            <uri>meshes/link_head.STL</uri>
          </mesh>
        </geometry>
        <material>
          <ambient>0.114435 0.114435 0.114435 1</ambient>
          <diffuse>0.114435 0.114435 0.114435 1</diffuse>
          <specular>0.114435 0.114435 0.114435 1</specular>
        </material>
      </visual>
      <visual name='base_link_fixed_joint_lump__respeaker_base_visual_7'>
        <pose>-0.06996100322803465 0.1319645029192444 1.39832 6.299472870381203e-13 -6.333935162588983e-13 -3.132339464324081</pose>
        <geometry>
          <mesh>
            <scale>1 1 1</scale>
            <uri>meshes/link_respeaker.STL</uri>
          </mesh>
        </geometry>
        <material>
          <ambient>1 1 1 1</ambient>
          <diffuse>1 1 1 1</diffuse>
          <specular>1 1 1 1</specular>
        </material>
      </visual>
    </link>
    <joint name='joint_left_wheel' type='revolute'>
      <pose relative_to='base_link'>-0.00300000000001899 0.15765 0.0507999999999994 -1.5707963267949 2.958228394578794e-31 7.88745438253713e-16</pose>
      <parent>base_link</parent>
      <child>link_left_wheel</child>
      <axis>
        <xyz>0 0 1</xyz>
        <limit>
          <lower>-10000000000000000</lower>
          <upper>10000000000000000</upper>
        </limit>
        <dynamics>
          <damping>21.75</damping>
          <friction>10.48</friction>
          <spring_reference>0</spring_reference>
          <spring_stiffness>0</spring_stiffness>
        </dynamics>
      </axis>
    </joint>
    <link name='link_left_wheel'>
      <pose relative_to='joint_left_wheel'>0 0 0 0 0 0</pose>
      <inertial>
        <pose>1.2555462092223e-07 -3.54748938502514e-07 -0.0239581106165035 0 0 0</pose>
        <mass>0.01</mass>
        <inertia>
          <ixx>0.001</ixx>
          <ixy>0</ixy>
          <ixz>0</ixz>
          <iyy>0.001</iyy>
          <iyz>0</iyz>
          <izz>0.001</izz>
        </inertia>
      </inertial>
      <collision name='link_left_wheel_collision'>
        <pose>0 0 0 0 0 0</pose>
        <geometry>
          <mesh>
            <scale>1 1 1</scale>
            <uri>meshes/link_left_wheel.STL</uri>
          </mesh>
        </geometry>
      </collision>
      <visual name='link_left_wheel_visual'>
        <pose>0 0 0 0 0 0</pose>
        <geometry>
          <mesh>
            <scale>1 1 1</scale>
            <uri>meshes/link_left_wheel.STL</uri>
          </mesh>
        </geometry>
        <material>
          <ambient>0.114435 0.114435 0.114435 1</ambient>
          <diffuse>0.114435 0.114435 0.114435 1</diffuse>
          <specular>0.114435 0.114435 0.114435 1</specular>
        </material>
      </visual>
    </link>
    <joint name='joint_head_pan' type='revolute'>
      <pose relative_to='base_link'>0.003094209419046201 -3.153024363378165e-06 1.355400796291214 6.825316746557009e-08 -1.101929811856553e-05 -3.946432458240426e-05</pose>
      <parent>base_link</parent>
      <child>link_head_pan</child>
      <axis>
        <xyz>0 0 1</xyz>
        <limit>
          <lower>-3.8999999999999999</lower>
          <upper>1.5</upper>
          <effort>100</effort>
          <velocity>1</velocity>
        </limit>
        <dynamics>
          <spring_reference>0</spring_reference>
          <spring_stiffness>0</spring_stiffness>
        </dynamics>
      </axis>
    </joint>
    <link name='link_head_pan'>
      <pose relative_to='joint_head_pan'>0 0 0 0 0 0</pose>
      <inertial>
        <pose>-0.00116200255310878 0.0130365621706306 0.00137629842298681 0 0 0</pose>
        <mass>0.035858341182617</mass>
        <inertia>
          <ixx>0.001</ixx>
          <ixy>0</ixy>
          <ixz>0</ixz>
          <iyy>0.001</iyy>
          <iyz>0</iyz>
          <izz>0.001</izz>
        </inertia>
      </inertial>
      <collision name='link_head_pan_collision'>
        <pose>0 0 0 0 0 0</pose>
        <geometry>
          <mesh>
            <scale>1 1 1</scale>
            <uri>meshes/link_head_pan.STL</uri>
          </mesh>
        </geometry>
      </collision>
      <visual name='link_head_pan_visual'>
        <pose>0 0 0 0 0 0</pose>
        <geometry>
          <mesh>
            <scale>1 1 1</scale>
            <uri>meshes/link_head_pan.STL</uri>
          </mesh>
        </geometry>
        <material>
          <ambient>0 0 0 1</ambient>
          <diffuse>0 0 0 1</diffuse>
          <specular>0 0 0 1</specular>
        </material>
      </visual>
    </link>
    <joint name='joint_head_tilt' type='revolute'>
      <pose relative_to='link_head_pan'>-0.0013 0.027507 -0.053311 1.5708 6.068000321709392e-24 -2.516500000000001e-15</pose>
      <parent>link_head_pan</parent>
      <child>link_head_tilt</child>
      <axis>
        <xyz>0 0 1</xyz>
        <limit>
          <lower>-1.53</lower>
          <upper>0.79000000000000004</upper>
          <effort>100</effort>
          <velocity>1</velocity>
        </limit>
        <dynamics>
          <spring_reference>0</spring_reference>
          <spring_stiffness>0</spring_stiffness>
        </dynamics>
      </axis>
    </joint>
    <link name='link_head_tilt'>
      <pose relative_to='joint_head_tilt'>0 0 0 0 0 0</pose>
      <inertial>
        <pose>0.02510825030051016 -0.01111667264468728 0.03067929868199617 0 0 0</pose>
        <mass>0.1421242408063442</mass>
        <inertia>
          <ixx>0.0049205711437744467</ixx>
          <ixy>-3.7112318914880303e-05</ixy>
          <ixz>-4.6798394068325092e-08</ixz>
          <iyy>0.001533961456203077</iyy>
          <iyz>-4.959245602462756e-08</iyz>
          <izz>0.0049536064749059914</izz>
        </inertia>
      </inertial>
      <collision name='link_head_tilt_collision'>
        <pose>0 0 0 0 0 0</pose>
        <geometry>
          <mesh>
            <scale>1 1 1</scale>
            <uri>meshes/link_head_tilt.STL</uri>
          </mesh>
        </geometry>
      </collision>
      <collision name='link_head_tilt_fixed_joint_lump__camera_link_collision_1'>
        <pose>0.0406 -0.0122 0.0307 0 0 0</pose>
        <geometry>
          <box>
            <size>0.02505 0.09 0.025</size>
          </box>
        </geometry>
      </collision>
      <visual name='link_head_tilt_visual'>
        <pose>0 0 0 0 0 0</pose>
        <geometry>
          <mesh>
            <scale>1 1 1</scale>
            <uri>meshes/link_head_tilt.STL</uri>
          </mesh>
        </geometry>
        <material>
          <ambient>0.114435 0.114435 0.114435 1</ambient>
          <diffuse>0.114435 0.114435 0.114435 1</diffuse>
          <specular>0.114435 0.114435 0.114435 1</specular>
        </material>
      </visual>
      <visual name='link_head_tilt_fixed_joint_lump__camera_link_visual_1'>
        <pose>0.0449 -0.0122 0.0307 1.570796326794896 0 1.570796326794896</pose>
        <geometry>
          <mesh>
            <scale>1 1 1</scale>
            <uri>file:///home/chintujaguar/ament_ws/install/realsense2_description/share/realsense2_description/meshes/d435.dae</uri>
          </mesh>
        </geometry>
        <material>
          <ambient>0.114435 0.114435 0.114435 1</ambient>
          <diffuse>0.114435 0.114435 0.114435 1</diffuse>
          <specular>0.114435 0.114435 0.114435 1</specular>
        </material>
      </visual>
    </link>
    <joint name='joint_lift' type='prismatic'>
      <pose relative_to='base_link'>-0.1069232869348887 0.1349999999999974 0.1938711999999961 6.035042888065779e-15 2.304846663958401e-15 1.570796326794912</pose>
      <parent>base_link</parent>
      <child>link_lift</child>
      <axis>
        <xyz>0 0 1</xyz>
        <limit>
          <lower>0</lower>
          <upper>1.1000000000000001</upper>
          <effort>100</effort>
          <velocity>1</velocity>
        </limit>
        <dynamics>
          <spring_reference>0</spring_reference>
          <spring_stiffness>0</spring_stiffness>
        </dynamics>
      </axis>
    </joint>
    <link name='link_lift'>
      <pose relative_to='joint_lift'>0 0 0 0 0 0</pose>
      <inertial>
        <pose>-0.06857485624729062 0.03306528126703052 0.00809996375411043 0 0 0</pose>
        <mass>0.51247337681498051</mass>
        <inertia>
          <ixx>0.0016575125096314469</ixx>
          <ixy>-0.00048008898643292361</ixy>
          <ixz>-0.00018541637066102069</ixz>
          <iyy>0.002918936656085776</iyy>
          <iyz>-1.325010472769572e-05</iyz>
          <izz>0.003100916287324756</izz>
        </inertia>
      </inertial>
      <collision name='link_lift_collision'>
        <pose>0 0 0 0 0 0</pose>
        <geometry>
          <mesh>
            <scale>1 1 1</scale>
            <uri>meshes/link_lift.STL</uri>
          </mesh>
        </geometry>
      </collision>
      <collision name='link_lift_fixed_joint_lump__link_arm_l4_collision_1'>
        <pose>-0.25471 0 0 1.5708 -2.775557561562891e-16 -1.5708</pose>
        <geometry>
          <mesh>
            <scale>1 1 1</scale>
            <uri>meshes/link_arm_l4.STL</uri>
          </mesh>
        </geometry>
      </collision>
      <collision name='link_lift_fixed_joint_lump__link_aruco_shoulder_collision_2'>
        <pose>-0.0133768876375287 0.0558540528812078 0.0861368272417975 -1.53998860117704e-29 3.55962409571165e-15 0</pose>
        <geometry>
          <mesh>
            <scale>1 1 1</scale>
            <uri>meshes/link_aruco_shoulder.STL</uri>
          </mesh>
        </geometry>
      </collision>
      <visual name='link_lift_visual'>
        <pose>0 0 -0.001 0 0 0</pose>
        <geometry>
          <mesh>
            <scale>1 1 1</scale>
            <uri>meshes/link_lift.STL</uri>
          </mesh>
        </geometry>
        <material>
          <ambient>0.114435 0.114435 0.114435 1</ambient>
          <diffuse>0.114435 0.114435 0.114435 1</diffuse>
          <specular>0.114435 0.114435 0.114435 1</specular>
        </material>
      </visual>
      <visual name='link_lift_fixed_joint_lump__link_arm_l4_visual_1'>
        <pose>-0.25471 0 0 1.5708 -2.775557561562891e-16 -1.5708</pose>
        <geometry>
          <mesh>
            <scale>1 1 1</scale>
            <uri>meshes/link_arm_l4.STL</uri>
          </mesh>
        </geometry>
        <material>
          <ambient>0.061246 0.061246 0.061246 1</ambient>
          <diffuse>0.061246 0.061246 0.061246 1</diffuse>
          <specular>0.061246 0.061246 0.061246 1</specular>
        </material>
      </visual>
      <visual name='link_lift_fixed_joint_lump__link_aruco_shoulder_visual_2'>
        <pose>-0.0133768876375287 0.0558540528812078 0.0861368272417975 -1.53998860117704e-29 3.55962409571165e-15 0</pose>
        <geometry>
          <mesh>
            <scale>1 1 1</scale>
            <uri>meshes/link_aruco_shoulder.STL</uri>
          </mesh>
        </geometry>
        <material>
          <ambient>1 1 1 1</ambient>
          <diffuse>1 1 1 1</diffuse>
          <specular>1 1 1 1</specular>
        </material>
      </visual>
    </link>
    <joint name='joint_arm_l3' type='prismatic'>
      <pose relative_to='link_lift'>-0.2677099999998246 4.775166634329864e-08 -4.775166634676808e-08 1.570800000000001 -5.551115123125783e-17 -1.5708</pose>
      <parent>link_lift</parent>
      <child>link_arm_l3</child>
      <axis>
        <xyz>0 0 1</xyz>
        <limit>
          <lower>0</lower>
          <upper>0.13</upper>
          <effort>100</effort>
          <velocity>1</velocity>
        </limit>
        <dynamics>
          <spring_reference>0</spring_reference>
          <spring_stiffness>0</spring_stiffness>
        </dynamics>
      </axis>
    </joint>
    <link name='link_arm_l3'>
      <pose relative_to='joint_arm_l3'>0 0 0 0 0 0</pose>
      <inertial>
        <pose>-3.34873468621488e-07 4.7411336306924e-07 -0.0974069598289041 0 0 0</pose>
        <mass>0.062692104705840496</mass>
        <inertia>
          <ixx>0.001</ixx>
          <ixy>0</ixy>
          <ixz>0</ixz>
          <iyy>0.001</iyy>
          <iyz>0</iyz>
          <izz>0.001</izz>
        </inertia>
      </inertial>
      <collision name='link_arm_l3_collision'>
        <pose>0 0 0 0 0 0</pose>
        <geometry>
          <mesh>
            <scale>1 1 1</scale>
            <uri>meshes/link_arm_l3.STL</uri>
          </mesh>
        </geometry>
      </collision>
      <visual name='link_arm_l3_visual'>
        <pose>0 0 0 0 0 0</pose>
        <geometry>
          <mesh>
            <scale>1 1 1</scale>
            <uri>meshes/link_arm_l3.STL</uri>
          </mesh>
        </geometry>
        <material>
          <ambient>0.061246 0.061246 0.061246 1</ambient>
          <diffuse>0.061246 0.061246 0.061246 1</diffuse>
          <specular>0.061246 0.061246 0.061246 1</specular>
        </material>
      </visual>
    </link>
    <joint name='joint_arm_l2' type='prismatic'>
      <pose relative_to='link_arm_l3'>0 0 0.013 2.91385731014123e-16 4.44300759504684e-17 3.25691080516352e-16</pose>
      <parent>link_arm_l3</parent>
      <child>link_arm_l2</child>
      <axis>
        <xyz>0 0 1</xyz>
        <limit>
          <lower>0</lower>
          <upper>0.13</upper>
          <effort>100</effort>
          <velocity>1</velocity>
        </limit>
        <dynamics>
          <spring_reference>0</spring_reference>
          <spring_stiffness>0</spring_stiffness>
        </dynamics>
      </axis>
    </joint>
    <link name='link_arm_l2'>
      <pose relative_to='joint_arm_l2'>0 0 0 0 0 0</pose>
      <inertial>
        <pose>-3.31043560508615e-07 3.13422303999111e-07 -0.09725588354189101 0 0 0</pose>
        <mass>0.056907436857623797</mass>
        <inertia>
          <ixx>0.001</ixx>
          <ixy>0</ixy>
          <ixz>0</ixz>
          <iyy>0.001</iyy>
          <iyz>0</iyz>
          <izz>0.001</izz>
        </inertia>
      </inertial>
      <collision name='link_arm_l2_collision'>
        <pose>0 0 0 0 0 0</pose>
        <geometry>
          <mesh>
            <scale>1 1 1</scale>
            <uri>meshes/link_arm_l2.STL</uri>
          </mesh>
        </geometry>
      </collision>
      <visual name='link_arm_l2_visual'>
        <pose>0 0 0 0 0 0</pose>
        <geometry>
          <mesh>
            <scale>1 1 1</scale>
            <uri>meshes/link_arm_l2.STL</uri>
          </mesh>
        </geometry>
        <material>
          <ambient>0.061246 0.061246 0.061246 1</ambient>
          <diffuse>0.061246 0.061246 0.061246 1</diffuse>
          <specular>0.061246 0.061246 0.061246 1</specular>
        </material>
      </visual>
    </link>
    <joint name='joint_arm_l1' type='prismatic'>
      <pose relative_to='link_arm_l2'>0 0 0.013 7.41596560408007e-17 1.33876788296791e-16 -2.44545873596083e-16</pose>
      <parent>link_arm_l2</parent>
      <child>link_arm_l1</child>
      <axis>
        <xyz>0 0 1</xyz>
        <limit>
          <lower>0</lower>
          <upper>0.13</upper>
          <effort>100</effort>
          <velocity>1</velocity>
        </limit>
        <dynamics>
          <spring_reference>0</spring_reference>
          <spring_stiffness>0</spring_stiffness>
        </dynamics>
      </axis>
    </joint>
    <link name='link_arm_l1'>
      <pose relative_to='joint_arm_l1'>0 0 0 0 0 0</pose>
      <inertial>
        <pose>-3.36876635420591e-07 3.05876091066803e-07 -0.09691170322327559 0 0 0</pose>
        <mass>0.0511763619538321</mass>
        <inertia>
          <ixx>0.001</ixx>
          <ixy>0</ixy>
          <ixz>0</ixz>
          <iyy>0.001</iyy>
          <iyz>0</iyz>
          <izz>0.001</izz>
        </inertia>
      </inertial>
      <collision name='link_arm_l1_collision'>
        <pose>0 0 0 0 0 0</pose>
        <geometry>
          <mesh>
            <scale>1 1 1</scale>
            <uri>meshes/link_arm_l1.STL</uri>
          </mesh>
        </geometry>
      </collision>
      <visual name='link_arm_l1_visual'>
        <pose>0 0 0 0 0 0</pose>
        <geometry>
          <mesh>
            <scale>1 1 1</scale>
            <uri>meshes/link_arm_l1.STL</uri>
          </mesh>
        </geometry>
        <material>
          <ambient>0.061246 0.061246 0.061246 1</ambient>
          <diffuse>0.061246 0.061246 0.061246 1</diffuse>
          <specular>0.061246 0.061246 0.061246 1</specular>
        </material>
      </visual>
    </link>
    <joint name='joint_arm_l0' type='prismatic'>
      <pose relative_to='link_arm_l1'>0 0 -0.0137499999999938 -3.05317390622457e-16 -4.23236224076729e-16 -2.68425135229209e-17</pose>
      <parent>link_arm_l1</parent>
      <child>link_arm_l0</child>
      <axis>
        <xyz>0 0 1</xyz>
        <limit>
          <lower>0</lower>
          <upper>0.13</upper>
          <effort>100</effort>
          <velocity>1</velocity>
        </limit>
        <dynamics>
          <spring_reference>0</spring_reference>
          <spring_stiffness>0</spring_stiffness>
        </dynamics>
      </axis>
    </joint>
    <link name='link_arm_l0'>
      <pose relative_to='joint_arm_l0'>0 0 0 0 0 0</pose>
      <inertial>
        <pose>0.0230715049668191 -0.001951158336628179 -0.0360646347160285 0 0 0</pose>
        <mass>0.101241250325294</mass>
        <inertia>
          <ixx>0.001</ixx>
          <ixy>0</ixy>
          <ixz>0</ixz>
          <iyy>0.001</iyy>
          <iyz>-8.4703294725430034e-22</iyz>
          <izz>0.001</izz>
        </inertia>
      </inertial>
      <collision name='link_arm_l0_collision'>
        <pose>0 0 0 0 0 0</pose>
        <geometry>
          <mesh>
            <scale>1 1 1</scale>
            <uri>meshes/link_arm_l0.STL</uri>
          </mesh>
        </geometry>
      </collision>
      <collision name='link_arm_l0_fixed_joint_lump__link_aruco_inner_wrist_collision_1'>
        <pose>0.0472499999999947 -0.0119000000000034 -0.0272499999991938 3.14159265358979 4.23377442363088e-14 3.14159265358979</pose>
        <geometry>
          <mesh>
            <scale>1 1 1</scale>
            <uri>meshes/link_aruco_inner_wrist.STL</uri>
          </mesh>
        </geometry>
      </collision>
      <collision name='link_arm_l0_fixed_joint_lump__link_aruco_top_wrist_collision_2'>
        <pose>0.0472500000000019 0.0292850000000015 0 1.5707963267949 -8.03728587323464e-15 3.14159265358979</pose>
        <geometry>
          <mesh>
            <scale>1 1 1</scale>
            <uri>meshes/link_aruco_top_wrist.STL</uri>
          </mesh>
        </geometry>
      </collision>
      <visual name='link_arm_l0_visual'>
        <pose>0 0 0 0 0 0</pose>
        <geometry>
          <mesh>
            <scale>1 1 1</scale>
            <uri>meshes/link_arm_l0.STL</uri>
          </mesh>
        </geometry>
        <material>
          <ambient>0.061246 0.061246 0.061246 1</ambient>
          <diffuse>0.061246 0.061246 0.061246 1</diffuse>
          <specular>0.061246 0.061246 0.061246 1</specular>
        </material>
      </visual>
      <visual name='link_arm_l0_fixed_joint_lump__link_aruco_inner_wrist_visual_1'>
        <pose>0.0472499999999947 -0.0119000000000034 -0.0272499999991938 3.14159265358979 4.23377442363088e-14 3.14159265358979</pose>
        <geometry>
          <mesh>
            <scale>1 1 1</scale>
            <uri>meshes/link_aruco_inner_wrist.STL</uri>
          </mesh>
        </geometry>
        <material>
          <ambient>1 1 1 1</ambient>
          <diffuse>1 1 1 1</diffuse>
          <specular>1 1 1 1</specular>
        </material>
      </visual>
      <visual name='link_arm_l0_fixed_joint_lump__link_aruco_top_wrist_visual_2'>
        <pose>0.0472500000000019 0.0292850000000015 0 1.5707963267949 -8.03728587323464e-15 3.14159265358979</pose>
        <geometry>
          <mesh>
            <scale>1 1 1</scale>
            <uri>meshes/link_aruco_top_wrist.STL</uri>
          </mesh>
        </geometry>
        <material>
          <ambient>1 1 1 1</ambient>
          <diffuse>1 1 1 1</diffuse>
          <specular>1 1 1 1</specular>
        </material>
      </visual>
    </link>
    <joint name='joint_wrist_yaw' type='revolute'>
      <pose relative_to='link_arm_l0'>0.083 -0.03075 0 1.5708 4.259500000000001e-14 2.6415e-15</pose>
      <parent>link_arm_l0</parent>
      <child>link_wrist_yaw</child>
      <axis>
        <xyz>0 0 -1</xyz>
        <limit>
          <lower>-1.75</lower>
          <upper>4</upper>
          <effort>100</effort>
          <velocity>1</velocity>
        </limit>
        <dynamics>
          <spring_reference>0</spring_reference>
          <spring_stiffness>0</spring_stiffness>
        </dynamics>
      </axis>
    </joint>
    <link name='link_wrist_yaw'>
      <pose relative_to='joint_wrist_yaw'>0 0 0 0 0 0</pose>
      <inertial>
        <pose>-0.009403196397738539 0.01218365524548891 0.0319774822942111 0 0 0</pose>
        <mass>0.14244260952571691</mass>
        <inertia>
          <ixx>0.0020180073941767451</ixx>
          <ixy>6.4763096146507547e-06</ixy>
          <ixz>6.9376418272722496e-06</ixz>
          <iyy>0.002014624301545925</iyy>
          <iyz>-8.9824229691378465e-06</iyz>
          <izz>0.0020133871453509688</izz>
        </inertia>
      </inertial>
      <collision name='link_wrist_yaw_collision'>
        <pose>0 0 0 0 0 0</pose>
        <geometry>
          <mesh>
            <scale>1 1 1</scale>
            <uri>meshes/link_wrist_yaw.STL</uri>
          </mesh>
        </geometry>
      </collision>
      <collision name='link_wrist_yaw_fixed_joint_lump__link_gripper_collision_1'>
        <pose>0 0 0 3.14159 0 -1.5708</pose>
        <geometry>
          <mesh>
            <scale>1 1 1</scale>
            <uri>meshes/link_gripper.STL</uri>
          </mesh>
        </geometry>
      </collision>
      <visual name='link_wrist_yaw_visual'>
        <pose>0 0 0 0 0 0</pose>
        <geometry>
          <mesh>
            <scale>1 1 1</scale>
            <uri>meshes/link_wrist_yaw.STL</uri>
          </mesh>
        </geometry>
        <material>
          <ambient>0.036889 0.036889 0.036889 1</ambient>
          <diffuse>0.036889 0.036889 0.036889 1</diffuse>
          <specular>0.036889 0.036889 0.036889 1</specular>
        </material>
      </visual>
      <visual name='link_wrist_yaw_fixed_joint_lump__link_gripper_visual_1'>
        <pose>0 0 0 3.14159 0 -1.5708</pose>
        <geometry>
          <mesh>
            <scale>1 1 1</scale>
            <uri>meshes/link_gripper.STL</uri>
          </mesh>
        </geometry>
        <material>
          <ambient>0.036889 0.036889 0.036889 1</ambient>
          <diffuse>0.036889 0.036889 0.036889 1</diffuse>
          <specular>0.036889 0.036889 0.036889 1</specular>
        </material>
      </visual>
    </link>
    <joint name='joint_gripper_finger_left' type='revolute'>
      <pose relative_to='link_wrist_yaw'>0.01015129765051247 0.04723096271252031 0.0467899730632453 -3.141589589486062 -0.523599999978473 1.570783775124473</pose>
      <parent>link_wrist_yaw</parent>
      <child>link_gripper_finger_left</child>
      <axis>
        <xyz>0 0 1</xyz>
        <limit>
          <lower>-0.59999999999999998</lower>
          <upper>0.59999999999999998</upper>
          <effort>100</effort>
          <velocity>1</velocity>
        </limit>
        <dynamics>
          <spring_reference>0</spring_reference>
          <spring_stiffness>0</spring_stiffness>
        </dynamics>
      </axis>
    </joint>
    <link name='link_gripper_finger_left'>
      <pose relative_to='joint_gripper_finger_left'>0 0 0 0 0 0</pose>
      <inertial>
        <pose>0.1005292466057058 0.01211190923264307 -2.000871148061272e-09 0 0 0</pose>
        <mass>0.051442377694504687</mass>
        <inertia>
          <ixx>0.0020000649037258539</ixx>
          <ixy>1.2288302458767231e-06</ixy>
          <ixz>7.727024668562392e-12</ixz>
          <iyy>0.0020232655945920629</iyy>
          <iyz>-4.0812202696071278e-13</iyz>
          <izz>0.0020233304983179119</izz>
        </inertia>
      </inertial>
      <collision name='link_gripper_finger_left_collision'>
        <pose>0 0 0 0 0 0</pose>
        <geometry>
          <mesh>
            <scale>0.9 1 1</scale>
            <uri>meshes/link_gripper_finger_left.STL</uri>
          </mesh>
        </geometry>
      </collision>
      <collision name='link_gripper_finger_left_fixed_joint_lump__link_gripper_fingertip_left_collision_1'>
        <pose>0.171099 0.014912 0 -1.5708 -4.718447854656915e-15 -2.5545</pose>
        <geometry>
          <mesh>
            <scale>1 1 1</scale>
            <uri>meshes/link_gripper_fingertip_left.STL</uri>
          </mesh>
        </geometry>
      </collision>
      <visual name='link_gripper_finger_left_visual'>
        <pose>0 0 0 0 0 0</pose>
        <geometry>
          <mesh>
            <scale>0.9 1 1</scale>
            <uri>meshes/link_gripper_finger_left.STL</uri>
          </mesh>
        </geometry>
        <material>
          <ambient>0.473531 0.479320 0.485150 1</ambient>
          <diffuse>0.473531 0.479320 0.485150 1</diffuse>
          <specular>0.473531 0.479320 0.485150 1</specular>
        </material>
      </visual>
      <visual name='link_gripper_finger_left_fixed_joint_lump__link_gripper_fingertip_left_visual_1'>
        <pose>0.171099 0.014912 0 -1.5708 -4.718447854656915e-15 -2.5545</pose>
        <geometry>
          <mesh>
            <scale>1 1 1</scale>
            <uri>meshes/link_gripper_fingertip_left.STL</uri>
          </mesh>
        </geometry>
        <material>
          <ambient>0 0 0 1</ambient>
          <diffuse>0 0 0 1</diffuse>
          <specular>0 0 0 1</specular>
        </material>
      </visual>
    </link>
    <joint name='joint_gripper_finger_right' type='revolute'>
      <pose relative_to='link_wrist_yaw'>-0.01004870234928015 0.0472310369112634 0.04679002666575912 4.28230647754996e-06 0.5235999999979674 -1.570801532055115</pose>
      <parent>link_wrist_yaw</parent>
      <child>link_gripper_finger_right</child>
      <axis>
        <xyz>0 0 1</xyz>
        <limit>
          <lower>-0.59999999999999998</lower>
          <upper>0.59999999999999998</upper>
          <effort>100</effort>
          <velocity>1</velocity>
        </limit>
        <dynamics>
          <spring_reference>0</spring_reference>
          <spring_stiffness>0</spring_stiffness>
        </dynamics>
      </axis>
    </joint>
    <link name='link_gripper_finger_right'>
      <pose relative_to='joint_gripper_finger_right'>0 0 0 0 0 0</pose>
      <inertial>
        <pose>-0.1005292232932491 -0.01211189260380338 -2.71579622671041e-09 0 0 0</pose>
        <mass>0.051442378893143549</mass>
        <inertia>
          <ixx>0.0020000649104908292</ixx>
          <ixy>1.228889351493392e-06</ixy>
          <ixz>-1.048790264165516e-11</ixz>
          <iyy>0.0020232654077798188</iyy>
          <iyz>5.5397575653042635e-13</iyz>
          <izz>0.002023330318270638</izz>
        </inertia>
      </inertial>
      <collision name='link_gripper_finger_right_collision'>
        <pose>0 0 0 0 0 0</pose>
        <geometry>
          <mesh>
            <scale>0.9 1 1</scale>
            <uri>meshes/link_gripper_finger_right.STL</uri>
          </mesh>
        </geometry>
      </collision>
      <collision name='link_gripper_finger_right_fixed_joint_lump__link_gripper_fingertip_right_collision_1'>
        <pose>-0.171099 -0.014912 0 -1.5708 -2.05391259555654e-15 0.5870499999999998</pose>
        <geometry>
          <mesh>
            <scale>1 1 1</scale>
            <uri>meshes/link_gripper_fingertip_right.STL</uri>
          </mesh>
        </geometry>
      </collision>
      <visual name='link_gripper_finger_right_visual'>
        <pose>0 0 0 0 0 0</pose>
        <geometry>
          <mesh>
            <scale>0.9 1 1</scale>
            <uri>meshes/link_gripper_finger_right.STL</uri>
          </mesh>
        </geometry>
        <material>
          <ambient>0.473531 0.479320 0.485150 1</ambient>
          <diffuse>0.473531 0.479320 0.485150 1</diffuse>
          <specular>0.473531 0.479320 0.485150 1</specular>
        </material>
      </visual>
      <visual name='link_gripper_finger_right_fixed_joint_lump__link_gripper_fingertip_right_visual_1'>
        <pose>-0.171099 -0.014912 0 -1.5708 -2.05391259555654e-15 0.5870499999999998</pose>
        <geometry>
          <mesh>
            <scale>1 1 1</scale>
            <uri>meshes/link_gripper_fingertip_right.STL</uri>
          </mesh>
        </geometry>
        <material>
          <ambient>0 0 0 1</ambient>
          <diffuse>0 0 0 1</diffuse>
          <specular>0 0 0 1</specular>
        </material>
      </visual>
    </link>
    <joint name='joint_right_wheel' type='revolute'>
      <pose relative_to='base_link'>-0.00300000000000034 -0.15765 0.0508000000000004 -1.57079632679489 -1.11022302462516e-16 7.285838599102771e-17</pose>
      <parent>base_link</parent>
      <child>link_right_wheel</child>
      <axis>
        <xyz>0 0 1</xyz>
        <limit>
          <lower>-10000000000000000</lower>
          <upper>10000000000000000</upper>
        </limit>
        <dynamics>
          <damping>21.75</damping>
          <friction>10.48</friction>
          <spring_reference>0</spring_reference>
          <spring_stiffness>0</spring_stiffness>
        </dynamics>
      </axis>
    </joint>
    <link name='link_right_wheel'>
      <pose relative_to='joint_right_wheel'>0 0 0 0 0 0</pose>
      <inertial>
        <pose>1.25554620866719e-07 3.54748938447003e-07 0.0239581106165018 0 0 0</pose>
        <mass>0.01</mass>
        <inertia>
          <ixx>0.001</ixx>
          <ixy>0</ixy>
          <ixz>0</ixz>
          <iyy>0.001</iyy>
          <iyz>0</iyz>
          <izz>0.001</izz>
        </inertia>
      </inertial>
      <collision name='link_right_wheel_collision'>
        <pose>0 0 0 0 0 0</pose>
        <geometry>
          <mesh>
            <scale>1 1 1</scale>
            <uri>meshes/link_right_wheel.STL</uri>
          </mesh>
        </geometry>
      </collision>
      <visual name='link_right_wheel_visual'>
        <pose>0 0 0 0 0 0</pose>
        <geometry>
          <mesh>
            <scale>1 1 1</scale>
            <uri>meshes/link_right_wheel.STL</uri>
          </mesh>
        </geometry>
        <material>
          <ambient>0.114435 0.114435 0.114435 1</ambient>
          <diffuse>0.114435 0.114435 0.114435 1</diffuse>
          <specular>0.114435 0.114435 0.114435 1</specular>
        </material>
      </visual>
    </link>
    <frame name='caster_joint' attached_to='base_link'>
      <pose>-0.245 0 0.032 -1.5708 0 0</pose>
    </frame>
    <frame name='caster_link' attached_to='caster_joint'/>
    <frame name='joint_aruco_left_base' attached_to='base_link'>
      <pose>-0.005 0.130497 0.159748 0 0 -1.5708</pose>
    </frame>
    <frame name='link_aruco_left_base' attached_to='joint_aruco_left_base'/>
    <frame name='joint_aruco_right_base' attached_to='base_link'>
      <pose>-0.005 -0.130497 0.159748 0 0 -1.5708</pose>
    </frame>
    <frame name='link_aruco_right_base' attached_to='joint_aruco_right_base'/>
    <frame name='joint_laser' attached_to='base_link'>
      <pose>0.000503 0 0.1664 0 0 -3.14159</pose>
    </frame>
    <frame name='laser' attached_to='joint_laser'/>
    <frame name='joint_head' attached_to='link_mast'>
      <pose>0 1.33 0 1.5708 -1.5615 -3.14159</pose>
    </frame>
    <frame name='link_head' attached_to='joint_head'/>
    <frame name='camera_accel_optical_joint' attached_to='camera_accel_frame'>
      <pose>0 0 0 -1.5708 -0 -1.5708</pose>
    </frame>
    <frame name='camera_accel_optical_frame' attached_to='camera_accel_optical_joint'/>
    <frame name='camera_accel_joint' attached_to='camera_link'>
      <pose>-0.01174 -0.00552 0.0051 0 -0 0</pose>
    </frame>
    <frame name='camera_accel_frame' attached_to='camera_accel_joint'/>
    <frame name='camera_color_optical_joint' attached_to='camera_color_frame'>
      <pose>0 0 0 -1.5708 -0 -1.5708</pose>
    </frame>
    <frame name='camera_color_optical_frame' attached_to='camera_color_optical_joint'/>
    <frame name='camera_color_joint' attached_to='camera_link'>
      <pose>0 0.015 0 0 -0 0</pose>
    </frame>
    <frame name='camera_color_frame' attached_to='camera_color_joint'/>
    <frame name='camera_depth_optical_joint' attached_to='camera_depth_frame'>
      <pose>0 0 0 -1.5708 -0 -1.5708</pose>
    </frame>
    <frame name='camera_depth_optical_frame' attached_to='camera_depth_optical_joint'/>
    <frame name='camera_depth_joint' attached_to='camera_link'>
      <pose>0 0 0 0 -0 0</pose>
    </frame>
    <frame name='camera_depth_frame' attached_to='camera_depth_joint'/>
    <frame name='camera_gyro_optical_joint' attached_to='camera_gyro_frame'>
      <pose>0 0 0 -1.5708 -0 -1.5708</pose>
    </frame>
    <frame name='camera_gyro_optical_frame' attached_to='camera_gyro_optical_joint'/>
    <frame name='camera_gyro_joint' attached_to='camera_link'>
      <pose>-0.01174 -0.00552 0.0051 0 -0 0</pose>
    </frame>
    <frame name='camera_gyro_frame' attached_to='camera_gyro_joint'/>
    <frame name='camera_infra1_optical_joint' attached_to='camera_infra1_frame'>
      <pose>0 0 0 -1.5708 -0 -1.5708</pose>
    </frame>
    <frame name='camera_infra1_optical_frame' attached_to='camera_infra1_optical_joint'/>
    <frame name='camera_infra1_joint' attached_to='camera_link'>
      <pose>0 0 0 0 -0 0</pose>
    </frame>
    <frame name='camera_infra1_frame' attached_to='camera_infra1_joint'/>
    <frame name='camera_infra2_optical_joint' attached_to='camera_infra2_frame'>
      <pose>0 0 0 -1.5708 -0 -1.5708</pose>
    </frame>
    <frame name='camera_infra2_optical_frame' attached_to='camera_infra2_optical_joint'/>
    <frame name='camera_infra2_joint' attached_to='camera_link'>
      <pose>0 -0.05 0 0 -0 0</pose>
    </frame>
    <frame name='camera_infra2_frame' attached_to='camera_infra2_joint'/>
    <frame name='camera_link_joint' attached_to='camera_bottom_screw_frame'>
      <pose>0.0106 0.0175 0.0125 0 -0 0</pose>
    </frame>
    <frame name='camera_link' attached_to='camera_link_joint'/>
    <frame name='camera_joint' attached_to='link_head_tilt'>
      <pose>0.03 -0.0122 0.0182 0 -0 0</pose>
    </frame>
    <frame name='camera_bottom_screw_frame' attached_to='camera_joint'/>
    <frame name='joint_respeaker' attached_to='link_mast'>
      <pose>1.1e-05 1.36992 0.003036 1.5708 -0 3.14159</pose>
    </frame>
    <frame name='respeaker_base' attached_to='joint_respeaker'/>
    <frame name='joint_mast' attached_to='base_link'>
      <pose>-0.07 0.135 0.0284 1.5708 0 0.009253</pose>
    </frame>
    <frame name='link_mast' attached_to='joint_mast'/>
    <frame name='joint_arm_l4' attached_to='link_lift'>
      <pose>-0.25471 0 0 1.5708 -0 -1.5708</pose>
    </frame>
    <frame name='link_arm_l4' attached_to='joint_arm_l4'/>
    <frame name='joint_aruco_inner_wrist' attached_to='link_arm_l0'>
      <pose>0.04725 -0.0119 -0.02725 3.14159 0 3.14159</pose>
    </frame>
    <frame name='link_aruco_inner_wrist' attached_to='joint_aruco_inner_wrist'/>
    <frame name='joint_aruco_top_wrist' attached_to='link_arm_l0'>
      <pose>0.04725 0.029285 0 1.5708 -0 3.14159</pose>
    </frame>
    <frame name='link_aruco_top_wrist' attached_to='joint_aruco_top_wrist'/>
    <frame name='joint_grasp_center' attached_to='link_gripper'>
      <pose>-0.205478 0 -0.138154 0 -0 3.14158</pose>
    </frame>
    <frame name='link_grasp_center' attached_to='joint_grasp_center'/>
    <frame name='joint_gripper' attached_to='link_wrist_yaw'>
      <pose>0 0 0 3.14159 -0 -1.5708</pose>
    </frame>
    <frame name='link_gripper' attached_to='joint_gripper'/>
    <frame name='joint_gripper_fingertip_left' attached_to='link_gripper_finger_left'>
      <pose>0.171099 0.014912 0 -1.5708 -0 -2.5545</pose>
    </frame>
    <frame name='link_gripper_fingertip_left' attached_to='joint_gripper_fingertip_left'/>
    <frame name='joint_gripper_fingertip_right' attached_to='link_gripper_finger_right'>
      <pose>-0.171099 -0.014912 0 -1.5708 -0 0.58705</pose>
    </frame>
    <frame name='link_gripper_fingertip_right' attached_to='joint_gripper_fingertip_right'/>
    <frame name='joint_aruco_shoulder' attached_to='link_lift'>
      <pose>-0.013377 0.055854 0.086137 -0 0 0</pose>
    </frame>
    <frame name='link_aruco_shoulder' attached_to='joint_aruco_shoulder'/>

    <plugin
      filename="libignition-gazebo-diff-drive-system.so"
      name="ignition::gazebo::systems::DiffDrive">
      <left_joint>joint_left_wheel</left_joint>
      <right_joint>joint_right_wheel</right_joint>
      <wheel_separation>0.3153</wheel_separation>
      <wheel_radius>0.1016</wheel_radius>
      <odom_publish_frequency>1</odom_publish_frequency>
      <topic>/stretch/cmd_vel</topic>
    </plugin>
  </model>
</sdf>
