<sdf version='1.9'>
  <model name='Hello Robot Stretch 2'>
    <static>false</static>
    <self_collide>false</self_collide>
    <allow_auto_disable>true</allow_auto_disable>
    <enable_wind>false</enable_wind>
    <pose>0 0 0 0 0 0</pose>
    <link name='base_link'>
      <pose>0 0 0 0 0 0</pose>
      <inertial>
        <pose>-0.10805757336290704 0.0017275253324131007 0.092531032970930627 -1.5670634314167264 -1.5470191929099661 3.140361552967474</pose>
        <mass>15</mass>
        <inertia>
          <ixx>0.22862750364637155</ixx>
          <ixy>0</ixy>
          <ixz>0</ixz>
          <iyy>0.13815207309617519</iyy>
          <iyz>0</iyz>
          <izz>0.13205250544800534</izz>
        </inertia>
      </inertial>
      <enable_wind>false</enable_wind>
      <collision name='collision_0'>
        <pose>0 0 0 0 0 0</pose>
        <geometry>
          <mesh>
            <uri>meshes/base_link_casterless.stl</uri>
            <scale>1 1 1</scale>
          </mesh>
        </geometry>
        <surface>
          <contact>
            <collide_bitmask>255</collide_bitmask>
          </contact>
          <friction>
            <ode>
              <mu>1</mu>
              <mu2>1</mu2>
              <slip1>0</slip1>
              <slip2>0</slip2>
              <fdir1>0 0 0</fdir1>
            </ode>
          </friction>
        </surface>
      </collision>
      <collision name='collision_1'>
        <pose>-0.23999999999999999 0 0.02 0 0 0</pose>
        <geometry>
          <sphere>
            <radius>0.02</radius>
          </sphere>
        </geometry>
        <surface>
          <contact>
            <collide_bitmask>255</collide_bitmask>
          </contact>
          <friction>
            <ode>
              <mu>1</mu>
              <mu2>1</mu2>
              <slip1>0</slip1>
              <slip2>0</slip2>
              <fdir1>0 0 0</fdir1>
            </ode>
          </friction>
        </surface>
      </collision>
    </link>
    <link name='link_mast'>
      <pose relative_to='base_link'>-0.067000000000000004 0.13500000000000001 0.028400000000000002 1.5707963267948963 0 0</pose>
      <inertial>
        <pose>7.7176490120826039e-19 0.70749999552045784 5.6747419206489729e-20 1.5707963267948963 0 0</pose>
        <mass>1.8285</mass>
        <inertia>
          <ixx>0.25181815723669448</ixx>
          <ixy>0</ixy>
          <ixz>0</ixz>
          <iyy>0.25181815723335327</iyy>
          <iyz>0</iyz>
          <izz>0.00042547450864685696</izz>
        </inertia>
      </inertial>
      <enable_wind>false</enable_wind>
      <collision name='collision_0'>
        <pose>0 0 0 0 0 0</pose>
        <geometry>
          <mesh>
            <uri>meshes/link_mast_color.obj</uri>
            <scale>1 1 1</scale>
          </mesh>
        </geometry>
        <surface>
          <contact>
            <collide_bitmask>255</collide_bitmask>
          </contact>
          <friction>
            <ode>
              <mu>1</mu>
              <mu2>1</mu2>
              <slip1>0</slip1>
              <slip2>0</slip2>
              <fdir1>0 0 0</fdir1>
            </ode>
          </friction>
        </surface>
      </collision>
      <visual name='link_mast_vis'>
        <geometry>
          <mesh>
            <scale>1 1 1</scale>
            <uri>meshes/link_mast.obj</uri>
          </mesh>

          <material>
            <script name='pink'>
              <uri>meshes/link_mast_color.obj.mtl</uri>
            </script>
          </material>
        </geometry>
      </visual>
    </link>
    <link name='link_head'>
      <pose relative_to='base_link'>-0.067000000000000004 0.134995 1.3584000000000001 0 0 -1.5707963267948963</pose>
      <inertial>
        <pose>0.040602571974930446 0.039964508907838828 0.031247858538322484 -2.1549602970640804 -1.5609040083956027 -0.5326449934713865</pose>
        <mass>0.83302723671869106</mass>
        <inertia>
          <ixx>0.0032788538554505329</ixx>
          <ixy>0</ixy>
          <ixz>0</ixz>
          <iyy>0.0027109996968740628</iyy>
          <iyz>0</iyz>
          <izz>0.00079228074269074638</izz>
        </inertia>
      </inertial>
      <enable_wind>false</enable_wind>
      <collision name='collision_0'>
        <pose>0 0 0 0 0 0</pose>
        <geometry>
          <mesh>
            <uri>meshes/link_head_10.obj</uri>
            <scale>1 1 1</scale>
          </mesh>
        </geometry>
        <surface>
          <contact>
            <collide_bitmask>255</collide_bitmask>
          </contact>
          <friction>
            <ode>
              <mu>1</mu>
              <mu2>1</mu2>
              <slip1>0</slip1>
              <slip2>0</slip2>
              <fdir1>0 0 0</fdir1>
            </ode>
          </friction>
        </surface>
      </collision>
    </link>
    <link name='link_aruco_right_base'>
      <pose relative_to='base_link'>-0.0015028000000000001 -0.130497 0.159748 0 0 -1.5707963267948963</pose>
      <inertial>
        <pose>2.0004131783513126e-11 -1.2996222396466522e-10 -3.1249943277331833e-05 -3.1415926535897931 -1.5707963267948966 0</pose>
        <mass>3.5999999999999998e-06</mass>
        <inertia>
          <ixx>2.1730643342061799e-09</ixx>
          <ixy>0</ixy>
          <ixz>0</ixz>
          <iyy>1.0865881251842877e-09</iyy>
          <iyz>0</iyz>
          <izz>1.0865880975780643e-09</izz>
        </inertia>
      </inertial>
      <enable_wind>false</enable_wind>
      <collision name='collision_0'>
        <pose>0 0 0 0 0 0</pose>
        <geometry>
          <mesh>
            <uri>meshes/link_aruco_right_base.obj</uri>
            <scale>1 1 1</scale>
          </mesh>
        </geometry>
        <surface>
          <contact>
            <collide_bitmask>255</collide_bitmask>
          </contact>
          <friction>
            <ode>
              <mu>1</mu>
              <mu2>1</mu2>
              <slip1>0</slip1>
              <slip2>0</slip2>
              <fdir1>0 0 0</fdir1>
            </ode>
          </friction>
        </surface>
      </collision>
    </link>
    <link name='link_aruco_left_base'>
      <pose relative_to='base_link'>-0.0015028000000000001 0.130497 0.159748 0 0 -1.5707963267948963</pose>
      <inertial>
        <pose>2.0004131783513126e-11 -1.2996222396466522e-10 -3.1249943277331833e-05 -3.1415926535897931 -1.5707963267948966 0</pose>
        <mass>3.5999999999999998e-06</mass>
        <inertia>
          <ixx>2.1730643342061799e-09</ixx>
          <ixy>0</ixy>
          <ixz>0</ixz>
          <iyy>1.0865881251842877e-09</iyy>
          <iyz>0</iyz>
          <izz>1.0865880975780643e-09</izz>
        </inertia>
      </inertial>
      <enable_wind>false</enable_wind>
      <collision name='collision_0'>
        <pose>0 0 0 0 0 0</pose>
        <geometry>
          <mesh>
            <uri>meshes/link_aruco_left_base.obj</uri>
            <scale>1 1 1</scale>
          </mesh>
        </geometry>
        <surface>
          <contact>
            <collide_bitmask>255</collide_bitmask>
          </contact>
          <friction>
            <ode>
              <mu>1</mu>
              <mu2>1</mu2>
              <slip1>0</slip1>
              <slip2>0</slip2>
              <fdir1>0 0 0</fdir1>
            </ode>
          </friction>
        </surface>
      </collision>
    </link>
    <link name='laser'>
      <pose relative_to='base_link'>0.0040000000000000001 0 0.16639999999999999 0 0 3.1415926535897931</pose>
      <inertial>
        <pose>-6.3433709496860728e-12 -9.0040000382647127e-12 -0.00075138124831749349 2.9914933866171833 -1.5707963267948966 0</pose>
        <mass>0.23999999999999999</mass>
        <inertia>
          <ixx>0.00014657010991979438</ixx>
          <ixy>0</ixy>
          <ixz>0</ixz>
          <iyy>8.0878141684263897e-05</iyy>
          <iyz>0</iyz>
          <izz>8.0877580923360704e-05</izz>
        </inertia>
      </inertial>
      <enable_wind>false</enable_wind>
      <collision name='collision_0'>
        <pose>0 0 0 0 0 0</pose>
        <geometry>
          <mesh>
            <uri>meshes/laser.obj</uri>
            <scale>1 1 1</scale>
          </mesh>
        </geometry>
        <surface>
          <contact>
            <collide_bitmask>255</collide_bitmask>
          </contact>
          <friction>
            <ode>
              <mu>1</mu>
              <mu2>1</mu2>
              <slip1>0</slip1>
              <slip2>0</slip2>
              <fdir1>0 0 0</fdir1>
            </ode>
          </friction>
        </surface>
      </collision>
    </link>
    <link name='link_right_wheel'>
      <pose relative_to='base_link'>0 -0.17035 0.050799999999999998 -1.5707963267948963 0 0</pose>
      <inertial>
        <pose>-6.0671658473551543e-09 -2.7612684106726629e-09 0.012700001036857403 2.0345642191436424 -1.5707963267948966 0</pose>
        <mass>0.14999999999999999</mass>
        <inertia>
          <ixx>0.00020521951414797452</ixx>
          <ixy>0</ixy>
          <ixz>0</ixz>
          <iyy>0.00010773092036250454</iyy>
          <iyz>0</iyz>
          <izz>0.00010773069364450959</izz>
        </inertia>
      </inertial>
      <enable_wind>false</enable_wind>
      <collision name='collision_0'>
        <pose>0 0 0.012500000000000001 0 0 0</pose>
        <geometry>
          <cylinder>
            <radius>0.050000000000000003</radius>
            <length>0.025000000000000001</length>
          </cylinder>
        </geometry>
        <surface>
          <contact>
            <collide_bitmask>255</collide_bitmask>
          </contact>
          <friction>
            <ode>
              <mu>1</mu>
              <mu2>1</mu2>
              <slip1>0</slip1>
              <slip2>0</slip2>
              <fdir1>0 0 0</fdir1>
            </ode>
          </friction>
        </surface>
      </collision>
    </link>
    <link name='link_left_wheel'>
      <pose relative_to='base_link'>0 0.17035 0.050799999999999998 -1.5707963267948963 0 0</pose>
      <inertial>
        <pose>2.7612684106726629e-09 6.0671658473551543e-09 -0.012700001036857403 2.6777576317556822 -1.5707963267948966 0</pose>
        <mass>0.14999999999999999</mass>
        <inertia>
          <ixx>0.0002052195141479745</ixx>
          <ixy>0</ixy>
          <ixz>0</ixz>
          <iyy>0.00010773092038281194</iyy>
          <iyz>0</iyz>
          <izz>0.0001077306936242021</izz>
        </inertia>
      </inertial>
      <enable_wind>false</enable_wind>
      <collision name='collision_0'>
        <pose>0 0 -0.012500000000000001 0 0 0</pose>
        <geometry>
          <cylinder>
            <radius>0.050000000000000003</radius>
            <length>0.025000000000000001</length>
          </cylinder>
        </geometry>
        <surface>
          <contact>
            <collide_bitmask>255</collide_bitmask>
          </contact>
          <friction>
            <ode>
              <mu>1</mu>
              <mu2>1</mu2>
              <slip1>0</slip1>
              <slip2>0</slip2>
              <fdir1>0 0 0</fdir1>
            </ode>
          </friction>
        </surface>
      </collision>
    </link>
    <link name='link_lift'>
      <pose relative_to='base_link'>-0.10438500000000001 0.13499900000000001 0.69499999999999995 0 0 1.5707963267948963</pose>
      <inertial>
        <pose>-0.029792531234783023 0.035797927735517328 0.0064752772671957505 -1.5144365654125449 -0.87777246225129701 -2.6887350634730693</pose>
        <mass>3</mass>
        <inertia>
          <ixx>0.016710194735969013</ixx>
          <ixy>0</ixy>
          <ixz>0</ixz>
          <iyy>0.01548207283958671</iyy>
          <iyz>0</iyz>
          <izz>0.0058408222071408512</izz>
        </inertia>
      </inertial>
      <enable_wind>false</enable_wind>
      <collision name='collision_0'>
        <pose>0 0 0 0 0 0</pose>
        <geometry>
          <mesh>
            <uri>meshes/link_lift_0.obj</uri>
            <scale>1 1 1</scale>
          </mesh>
        </geometry>
        <surface>
          <contact>
            <collide_bitmask>255</collide_bitmask>
          </contact>
          <friction>
            <ode>
              <mu>1</mu>
              <mu2>1</mu2>
              <slip1>0</slip1>
              <slip2>0</slip2>
              <fdir1>0 0 0</fdir1>
            </ode>
          </friction>
        </surface>
      </collision>
      <collision name='collision_1'>
        <pose>0 0 0 0 0 0</pose>
        <geometry>
          <mesh>
            <uri>meshes/link_lift_2.obj</uri>
            <scale>1 1 1</scale>
          </mesh>
        </geometry>
        <surface>
          <contact>
            <collide_bitmask>255</collide_bitmask>
          </contact>
          <friction>
            <ode>
              <mu>1</mu>
              <mu2>1</mu2>
              <slip1>0</slip1>
              <slip2>0</slip2>
              <fdir1>0 0 0</fdir1>
            </ode>
          </friction>
        </surface>
      </collision>
      <collision name='collision_2'>
        <pose>0 0 0 0 0 0</pose>
        <geometry>
          <mesh>
            <uri>meshes/link_lift_3.obj</uri>
            <scale>1 1 1</scale>
          </mesh>
        </geometry>
        <surface>
          <contact>
            <collide_bitmask>255</collide_bitmask>
          </contact>
          <friction>
            <ode>
              <mu>1</mu>
              <mu2>1</mu2>
              <slip1>0</slip1>
              <slip2>0</slip2>
              <fdir1>0 0 0</fdir1>
            </ode>
          </friction>
        </surface>
      </collision>
      <collision name='collision_3'>
        <pose>0 0 0 0 0 0</pose>
        <geometry>
          <mesh>
            <uri>meshes/link_lift_4.obj</uri>
            <scale>1 1 1</scale>
          </mesh>
        </geometry>
        <surface>
          <contact>
            <collide_bitmask>255</collide_bitmask>
          </contact>
          <friction>
            <ode>
              <mu>1</mu>
              <mu2>1</mu2>
              <slip1>0</slip1>
              <slip2>0</slip2>
              <fdir1>0 0 0</fdir1>
            </ode>
          </friction>
        </surface>
      </collision>
      <collision name='collision_4'>
        <pose>0 0 0 0 0 0</pose>
        <geometry>
          <mesh>
            <uri>meshes/link_lift_5.obj</uri>
            <scale>1 1 1</scale>
          </mesh>
        </geometry>
        <surface>
          <contact>
            <collide_bitmask>255</collide_bitmask>
          </contact>
          <friction>
            <ode>
              <mu>1</mu>
              <mu2>1</mu2>
              <slip1>0</slip1>
              <slip2>0</slip2>
              <fdir1>0 0 0</fdir1>
            </ode>
          </friction>
        </surface>
      </collision>
      <collision name='collision_5'>
        <pose>0 0 0 0 0 0</pose>
        <geometry>
          <mesh>
            <uri>meshes/link_lift_6.obj</uri>
            <scale>1 1 1</scale>
          </mesh>
        </geometry>
        <surface>
          <contact>
            <collide_bitmask>255</collide_bitmask>
          </contact>
          <friction>
            <ode>
              <mu>1</mu>
              <mu2>1</mu2>
              <slip1>0</slip1>
              <slip2>0</slip2>
              <fdir1>0 0 0</fdir1>
            </ode>
          </friction>
        </surface>
      </collision>
      <collision name='collision_6'>
        <pose>0 0 0 0 0 0</pose>
        <geometry>
          <mesh>
            <uri>meshes/link_lift_7.obj</uri>
            <scale>1 1 1</scale>
          </mesh>
        </geometry>
        <surface>
          <contact>
            <collide_bitmask>255</collide_bitmask>
          </contact>
          <friction>
            <ode>
              <mu>1</mu>
              <mu2>1</mu2>
              <slip1>0</slip1>
              <slip2>0</slip2>
              <fdir1>0 0 0</fdir1>
            </ode>
          </friction>
        </surface>
      </collision>
      <collision name='collision_7'>
        <pose>0 0 0 0 0 0</pose>
        <geometry>
          <mesh>
            <uri>meshes/link_lift_8.obj</uri>
            <scale>1 1 1</scale>
          </mesh>
        </geometry>
        <surface>
          <contact>
            <collide_bitmask>255</collide_bitmask>
          </contact>
          <friction>
            <ode>
              <mu>1</mu>
              <mu2>1</mu2>
              <slip1>0</slip1>
              <slip2>0</slip2>
              <fdir1>0 0 0</fdir1>
            </ode>
          </friction>
        </surface>
      </collision>
      <collision name='collision_8'>
        <pose>0 0 0 0 0 0</pose>
        <geometry>
          <mesh>
            <uri>meshes/link_lift_9.obj</uri>
            <scale>1 1 1</scale>
          </mesh>
        </geometry>
        <surface>
          <contact>
            <collide_bitmask>255</collide_bitmask>
          </contact>
          <friction>
            <ode>
              <mu>1</mu>
              <mu2>1</mu2>
              <slip1>0</slip1>
              <slip2>0</slip2>
              <fdir1>0 0 0</fdir1>
            </ode>
          </friction>
        </surface>
      </collision>
    </link>
    <link name='link_arm_l4'>
      <pose relative_to='link_lift'>0 0 0 0 0 0</pose>
      <inertial>
        <pose>-0.13758155362473296 5.0494837084650593e-20 -3.3475534081658652e-19 1.5707963267948963 0 1.5707963267948963</pose>
        <mass>0.16809499999999999</mass>
        <inertia>
          <ixx>0.00042794322633254669</ixx>
          <ixy>0</ixy>
          <ixz>0</ixz>
          <iyy>0.00042794322633254669</iyy>
          <iyz>0</iyz>
          <izz>6.603641886509173e-05</izz>
        </inertia>
      </inertial>
      <enable_wind>false</enable_wind>
      <collision name='collision_0'>
        <pose>-0.25469999999999998 0 0 1.5707963267948963 0 -1.5707963267948963</pose>
        <geometry>
          <mesh>
            <uri>meshes/link_arm_l4_0.obj</uri>
            <scale>1 1 1</scale>
          </mesh>
        </geometry>
        <surface>
          <contact>
            <collide_bitmask>255</collide_bitmask>
          </contact>
          <friction>
            <ode>
              <mu>1</mu>
              <mu2>1</mu2>
              <slip1>0</slip1>
              <slip2>0</slip2>
              <fdir1>0 0 0</fdir1>
            </ode>
          </friction>
        </surface>
      </collision>
      <collision name='collision_1'>
        <pose>-0.25469999999999998 0 0 1.5707963267948963 0 -1.5707963267948963</pose>
        <geometry>
          <mesh>
            <uri>meshes/link_arm_l4_1.obj</uri>
            <scale>1 1 1</scale>
          </mesh>
        </geometry>
        <surface>
          <contact>
            <collide_bitmask>255</collide_bitmask>
          </contact>
          <friction>
            <ode>
              <mu>1</mu>
              <mu2>1</mu2>
              <slip1>0</slip1>
              <slip2>0</slip2>
              <fdir1>0 0 0</fdir1>
            </ode>
          </friction>
        </surface>
      </collision>
    </link>
    <link name='link_arm_l3'>
      <pose relative_to='link_arm_l4'>-0.26769999999999999 0 0 1.5707963267948963 0 -1.5707963267948963</pose>
      <inertial>
        <pose>1.7139734477106333e-19 -1.4951683267262969e-19 -0.11927350960565335 0 0 0</pose>
        <mass>0.16289300000000001</mass>
        <inertia>
          <ixx>0.00042493391753292323</ixx>
          <ixy>0</ixy>
          <ixz>0</ixz>
          <iyy>0.00042493391753292323</iyy>
          <iyz>0</iyz>
          <izz>5.3205301011382015e-05</izz>
        </inertia>
      </inertial>
      <enable_wind>false</enable_wind>
      <collision name='collision_0'>
        <pose>0 0 0 0 0 0</pose>
        <geometry>
          <mesh>
            <uri>meshes/link_arm_l3_0.obj</uri>
            <scale>1 1 1</scale>
          </mesh>
        </geometry>
        <surface>
          <contact>
            <collide_bitmask>255</collide_bitmask>
          </contact>
          <friction>
            <ode>
              <mu>1</mu>
              <mu2>1</mu2>
              <slip1>0</slip1>
              <slip2>0</slip2>
              <fdir1>0 0 0</fdir1>
            </ode>
          </friction>
        </surface>
      </collision>
      <collision name='collision_1'>
        <pose>0 0 0 0 0 0</pose>
        <geometry>
          <mesh>
            <uri>meshes/link_arm_l3_1.obj</uri>
            <scale>1 1 1</scale>
          </mesh>
        </geometry>
        <surface>
          <contact>
            <collide_bitmask>255</collide_bitmask>
          </contact>
          <friction>
            <ode>
              <mu>1</mu>
              <mu2>1</mu2>
              <slip1>0</slip1>
              <slip2>0</slip2>
              <fdir1>0 0 0</fdir1>
            </ode>
          </friction>
        </surface>
      </collision>
    </link>
    <link name='link_arm_l2'>
      <pose relative_to='link_arm_l3'>0 0 0.012999999999999999 0 0 0</pose>
      <inertial>
        <pose>-2.6938421654190089e-19 2.6938421654190089e-19 -0.11943428559206307 0 0 0</pose>
        <mass>0.157139</mass>
        <inertia>
          <ixx>0.00040654816046468907</ixx>
          <ixy>0</ixy>
          <ixz>0</ixz>
          <iyy>0.00040654816046468907</iyy>
          <iyz>0</iyz>
          <izz>4.1867667031101432e-05</izz>
        </inertia>
      </inertial>
      <enable_wind>false</enable_wind>
      <collision name='collision_0'>
        <pose>0 0 0 0 0 0</pose>
        <geometry>
          <mesh>
            <uri>meshes/link_arm_l2_0.obj</uri>
            <scale>1 1 1</scale>
          </mesh>
        </geometry>
        <surface>
          <contact>
            <collide_bitmask>255</collide_bitmask>
          </contact>
          <friction>
            <ode>
              <mu>1</mu>
              <mu2>1</mu2>
              <slip1>0</slip1>
              <slip2>0</slip2>
              <fdir1>0 0 0</fdir1>
            </ode>
          </friction>
        </surface>
      </collision>
      <collision name='collision_1'>
        <pose>0 0 0 0 0 0</pose>
        <geometry>
          <mesh>
            <uri>meshes/link_arm_l2_1.obj</uri>
            <scale>1 1 1</scale>
          </mesh>
        </geometry>
        <surface>
          <contact>
            <collide_bitmask>255</collide_bitmask>
          </contact>
          <friction>
            <ode>
              <mu>1</mu>
              <mu2>1</mu2>
              <slip1>0</slip1>
              <slip2>0</slip2>
              <fdir1>0 0 0</fdir1>
            </ode>
          </friction>
        </surface>
      </collision>
    </link>
    <link name='link_arm_l1'>
      <pose relative_to='link_arm_l2'>0 0 0.012999999999999999 0 0 0</pose>
      <inertial>
        <pose>1.6914572383675806e-19 1.6914572383675806e-19 -0.11963520706972523 0 0 1.5707963267948963</pose>
        <mass>0.15138199999999999</mass>
        <inertia>
          <ixx>0.00038916425269258794</ixx>
          <ixy>0</ixy>
          <ixz>0</ixz>
          <iyy>0.00038916425269258783</iyy>
          <iyz>0</iyz>
          <izz>3.2126779379642913e-05</izz>
        </inertia>
      </inertial>
      <enable_wind>false</enable_wind>
      <collision name='collision_0'>
        <pose>0 0 0 0 0 0</pose>
        <geometry>
          <mesh>
            <uri>meshes/link_arm_l1_0.obj</uri>
            <scale>1 1 1</scale>
          </mesh>
        </geometry>
        <surface>
          <contact>
            <collide_bitmask>255</collide_bitmask>
          </contact>
          <friction>
            <ode>
              <mu>1</mu>
              <mu2>1</mu2>
              <slip1>0</slip1>
              <slip2>0</slip2>
              <fdir1>0 0 0</fdir1>
            </ode>
          </friction>
        </surface>
      </collision>
      <collision name='collision_1'>
        <pose>0 0 0 0 0 0</pose>
        <geometry>
          <mesh>
            <uri>meshes/link_arm_l1_1.obj</uri>
            <scale>1 1 1</scale>
          </mesh>
        </geometry>
        <surface>
          <contact>
            <collide_bitmask>255</collide_bitmask>
          </contact>
          <friction>
            <ode>
              <mu>1</mu>
              <mu2>1</mu2>
              <slip1>0</slip1>
              <slip2>0</slip2>
              <fdir1>0 0 0</fdir1>
            </ode>
          </friction>
        </surface>
      </collision>
    </link>
    <link name='link_arm_l0'>
      <pose relative_to='link_arm_l1'>0 0 -0.01375 0 0 0</pose>
      <inertial>
        <pose>-2.6921297922042026e-09 2.6921355171613176e-09 -0.095133521482907407 0 0 0</pose>
        <mass>0.28500999999999999</mass>
        <inertia>
          <ixx>0.00070442583120787407</ixx>
          <ixy>0</ixy>
          <ixz>0</ixz>
          <iyy>0.00070442583120219253</iyy>
          <iyz>0</iyz>
          <izz>4.6924340618086328e-05</izz>
        </inertia>
      </inertial>
      <enable_wind>false</enable_wind>
      <collision name='collision_0'>
        <pose>0 0 0 0 0 0</pose>
        <geometry>
          <mesh>
            <uri>meshes/link_arm_l0_0.obj</uri>
            <scale>1 1 1</scale>
          </mesh>
        </geometry>
        <surface>
          <contact>
            <collide_bitmask>255</collide_bitmask>
          </contact>
          <friction>
            <ode>
              <mu>1</mu>
              <mu2>1</mu2>
              <slip1>0</slip1>
              <slip2>0</slip2>
              <fdir1>0 0 0</fdir1>
            </ode>
          </friction>
        </surface>
      </collision>
      <collision name='collision_1'>
        <pose>0 0 0 0 0 0</pose>
        <geometry>
          <mesh>
            <uri>meshes/link_arm_l0_1.obj</uri>
            <scale>1 1 1</scale>
          </mesh>
        </geometry>
        <surface>
          <contact>
            <collide_bitmask>255</collide_bitmask>
          </contact>
          <friction>
            <ode>
              <mu>1</mu>
              <mu2>1</mu2>
              <slip1>0</slip1>
              <slip2>0</slip2>
              <fdir1>0 0 0</fdir1>
            </ode>
          </friction>
        </surface>
      </collision>
      <collision name='collision_2'>
        <pose>0 0 0 0 0 0</pose>
        <geometry>
          <mesh>
            <uri>meshes/link_arm_l0_2.obj</uri>
            <scale>1 1 1</scale>
          </mesh>
        </geometry>
        <surface>
          <contact>
            <collide_bitmask>255</collide_bitmask>
          </contact>
          <friction>
            <ode>
              <mu>1</mu>
              <mu2>1</mu2>
              <slip1>0</slip1>
              <slip2>0</slip2>
              <fdir1>0 0 0</fdir1>
            </ode>
          </friction>
        </surface>
      </collision>
    </link>
    <link name='link_aruco_top_wrist'>
      <pose relative_to='link_arm_l0'>0.04725 0.029284999999999999 0 1.5707963267948963 0 3.1415926535897931</pose>
      <inertial>
        <pose>2.5678486295099414e-11 -4.2402612342800701e-12 -3.1249924335560423e-05 -3.1415926535897931 -1.5707963267948966 0</pose>
        <mass>3.5999999999999998e-06</mass>
        <inertia>
          <ixx>5.4429125981995082e-10</ixx>
          <ixy>0</ixy>
          <ixz>0</ixz>
          <iyy>2.7220128830018516e-10</iyy>
          <iyz>0</iyz>
          <izz>2.7220127254520287e-10</izz>
        </inertia>
      </inertial>
      <enable_wind>false</enable_wind>
      <collision name='collision_0'>
        <pose>0 0 0 0 0 0</pose>
        <geometry>
          <mesh>
            <uri>meshes/link_aruco_top_wrist.obj</uri>
            <scale>1 1 1</scale>
          </mesh>
        </geometry>
        <surface>
          <contact>
            <collide_bitmask>255</collide_bitmask>
          </contact>
          <friction>
            <ode>
              <mu>1</mu>
              <mu2>1</mu2>
              <slip1>0</slip1>
              <slip2>0</slip2>
              <fdir1>0 0 0</fdir1>
            </ode>
          </friction>
        </surface>
      </collision>
    </link>
    <link name='link_aruco_inner_wrist'>
      <pose relative_to='link_arm_l0'>0.04725 -0.011900000000000001 -0.02725 3.1415926535897931 0 3.1415926535897931</pose>
      <inertial>
        <pose>2.0721999296119757e-12 -3.2086809757671878e-11 -3.1249924335560423e-05 1.5707963267948963 -1.5707963267948966 0</pose>
        <mass>3.5999999999999998e-06</mass>
        <inertia>
          <ixx>5.4429125981995061e-10</ixx>
          <ixy>0</ixy>
          <ixz>0</ixz>
          <iyy>2.7220128830018505e-10</iyy>
          <iyz>0</iyz>
          <izz>2.7220127254520277e-10</izz>
        </inertia>
      </inertial>
      <enable_wind>false</enable_wind>
      <collision name='collision_0'>
        <pose>0 0 0 0 0 0</pose>
        <geometry>
          <mesh>
            <uri>meshes/link_aruco_inner_wrist.obj</uri>
            <scale>1 1 1</scale>
          </mesh>
        </geometry>
        <surface>
          <contact>
            <collide_bitmask>255</collide_bitmask>
          </contact>
          <friction>
            <ode>
              <mu>1</mu>
              <mu2>1</mu2>
              <slip1>0</slip1>
              <slip2>0</slip2>
              <fdir1>0 0 0</fdir1>
            </ode>
          </friction>
        </surface>
      </collision>
    </link>
    <link name='link_wrist_yaw'>
      <pose relative_to='link_arm_l0'>0.083000000000000004 -0.03075 0 1.5707963267948963 0 0</pose>
      <inertial>
        <pose>-0.0080543282458336966 0.026552863939706701 0.044847952373810077 2.546537217131088 -1.1318083311577272 -1.1120192722273761</pose>
        <mass>0.142377</mass>
        <inertia>
          <ixx>0.00023046795296940043</ixx>
          <ixy>0</ixy>
          <ixz>0</ixz>
          <iyy>0.00021567539185024073</iyy>
          <iyz>0</iyz>
          <izz>4.3401930256588808e-05</izz>
        </inertia>
      </inertial>
      <enable_wind>false</enable_wind>
      <collision name='collision_0'>
        <pose>0 0 0 0 0 0</pose>
        <geometry>
          <mesh>
            <uri>meshes/link_wrist_yaw.obj</uri>
            <scale>1 1 1</scale>
          </mesh>
        </geometry>
        <surface>
          <contact>
            <collide_bitmask>255</collide_bitmask>
          </contact>
          <friction>
            <ode>
              <mu>1</mu>
              <mu2>1</mu2>
              <slip1>0</slip1>
              <slip2>0</slip2>
              <fdir1>0 0 0</fdir1>
            </ode>
          </friction>
        </surface>
      </collision>
      <collision name='collision_1'>
        <pose>0 0 0 3.1415926535897931 0 -1.5707963267948963</pose>
        <geometry>
          <mesh>
            <uri>meshes/link_gripper_0.obj</uri>
            <scale>1 1 1</scale>
          </mesh>
        </geometry>
        <surface>
          <contact>
            <collide_bitmask>255</collide_bitmask>
          </contact>
          <friction>
            <ode>
              <mu>1</mu>
              <mu2>1</mu2>
              <slip1>0</slip1>
              <slip2>0</slip2>
              <fdir1>0 0 0</fdir1>
            </ode>
          </friction>
        </surface>
      </collision>
      <collision name='collision_2'>
        <pose>0 0 0 3.1415926535897931 0 -1.5707963267948963</pose>
        <geometry>
          <mesh>
            <uri>meshes/link_gripper_1.obj</uri>
            <scale>1 1 1</scale>
          </mesh>
        </geometry>
        <surface>
          <contact>
            <collide_bitmask>255</collide_bitmask>
          </contact>
          <friction>
            <ode>
              <mu>1</mu>
              <mu2>1</mu2>
              <slip1>0</slip1>
              <slip2>0</slip2>
              <fdir1>0 0 0</fdir1>
            </ode>
          </friction>
        </surface>
      </collision>
    </link>
    <link name='link_gripper_slider'>
      <pose relative_to='link_wrist_yaw'>0 0.047231000000000002 0.046789999999999998 -3.1415892723887673 -0.5235993717950771 1.570783707995923</pose>
      <inertial>
        <pose>0 0 0 0 0 0</pose>
        <mass>0.050000000000000003</mass>
        <inertia>
          <ixx>8.3333333333333344e-07</ixx>
          <ixy>0</ixy>
          <ixz>0</ixz>
          <iyy>1.5416666666666668e-05</iyy>
          <iyz>0</iyz>
          <izz>1.5416666666666668e-05</izz>
        </inertia>
      </inertial>
      <enable_wind>false</enable_wind>
    </link>
    <link name='link_gripper_finger_left'>
      <pose relative_to='link_gripper_slider'>0 0.0101513 0 0 0 0</pose>
      <inertial>
        <pose>0.1083966550422958 0.0058553932218191902 -5.3898265566256241e-08 1.5707963267948966 -5.5511151231257827e-17 1.6694896622690785</pose>
        <mass>0.037821599999999997</mass>
        <inertia>
          <ixx>9.7862572003635164e-05</ixx>
          <ixy>0</ixy>
          <ixz>0</ixz>
          <iyy>9.7745601032524673e-05</iyy>
          <iyz>0</iyz>
          <izz>5.7658921045524182e-07</izz>
        </inertia>
      </inertial>
      <enable_wind>false</enable_wind>
      <collision name='collision_0'>
        <pose>0.10000000000000001 0.0050000000000000001 0 1.5707963267948966 -5.5511151231257827e-17 1.6694903460617465</pose>
        <geometry>
          <box>
            <size>0.0085389400000000001 0.01048934 0.16</size>
          </box>
        </geometry>
        <surface>
          <contact>
            <collide_bitmask>255</collide_bitmask>
          </contact>
          <friction>
            <ode>
              <mu>1</mu>
              <mu2>1</mu2>
              <slip1>0</slip1>
              <slip2>0</slip2>
              <fdir1>0 0 0</fdir1>
            </ode>
          </friction>
        </surface>
      </collision>
      <collision name='collision_1'>
        <pose>0 0 0 0 0 0</pose>
        <geometry>
          <mesh>
            <uri>meshes/link_gripper_finger_left_1.obj</uri>
            <scale>0.90000000000000002 1 1</scale>
          </mesh>
        </geometry>
        <surface>
          <contact>
            <collide_bitmask>255</collide_bitmask>
          </contact>
          <friction>
            <ode>
              <mu>1</mu>
              <mu2>1</mu2>
              <slip1>0</slip1>
              <slip2>0</slip2>
              <fdir1>0 0 0</fdir1>
            </ode>
          </friction>
        </surface>
      </collision>
    </link>
    <link name='rubber_tip_left'>
      <pose relative_to='link_gripper_finger_left'>0.171099 0.014912 0 1.5707963267948963 0 0</pose>
      <inertial>
        <pose>-8.4448137138552379e-08 -9.8008618022914351e-08 0.010368396070372503 2.4833062385323701 -1.5707870621304898 1.4358879727714744</pose>
        <mass>0.0050000000000000001</mass>
        <inertia>
          <ixx>7.8564728070097951e-07</ixx>
          <ixy>0</ixy>
          <ixz>0</ixz>
          <iyy>4.481050693166439e-07</iyy>
          <iyz>0</iyz>
          <izz>4.4808770717437325e-07</izz>
        </inertia>
      </inertial>
      <enable_wind>false</enable_wind>
      <collision name='collision_0'>
        <pose>0 0 0.012 0 0 0</pose>
        <geometry>
          <cylinder>
            <radius>0.02</radius>
            <length>0.01</length>
          </cylinder>
        </geometry>
        <surface>
          <contact>
            <collide_bitmask>255</collide_bitmask>
          </contact>
          <friction>
            <ode>
              <mu>0.80000000000000004</mu>
              <mu2>1</mu2>
              <slip1>0</slip1>
              <slip2>0</slip2>
              <fdir1>0 0 0</fdir1>
            </ode>
          </friction>
        </surface>
      </collision>
    </link>
    <link name='rubber_tip_left_dummy_0'>
      <pose relative_to='rubber_tip_left'>0 0 0 0 0 0</pose>
      <inertial>
        <pose>0 0 0 0 0 0</pose>
        <mass>9.9999999999999995e-07</mass>
        <inertia>
          <ixx>3.9999999999999998e-07</ixx>
          <ixy>0</ixy>
          <ixz>0</ixz>
          <iyy>3.9999999999999998e-07</iyy>
          <iyz>0</iyz>
          <izz>3.9999999999999998e-07</izz>
        </inertia>
      </inertial>
      <enable_wind>false</enable_wind>
    </link>
    <link name='link_gripper_finger_right'>
      <pose relative_to='link_gripper_slider'>0 -0.010048700000000001 0 3.1415926535897931 0 3.1415926535897931</pose>
      <inertial>
        <pose>-0.1083966550422958 -0.0058553932218191902 -5.3898265566256241e-08 1.5707963267948966 -5.5511151231257827e-17 1.6694896622690785</pose>
        <mass>0.037821599999999997</mass>
        <inertia>
          <ixx>9.7862572003635164e-05</ixx>
          <ixy>0</ixy>
          <ixz>0</ixz>
          <iyy>9.7745601032524673e-05</iyy>
          <iyz>0</iyz>
          <izz>5.7658921045524182e-07</izz>
        </inertia>
      </inertial>
      <enable_wind>false</enable_wind>
      <collision name='collision_0'>
        <pose>-0.10000000000000001 -0.0050000000000000001 0 1.5707963267948966 -5.5511151231257827e-17 1.6694903460617465</pose>
        <geometry>
          <box>
            <size>0.0085389400000000001 0.01048934 0.16</size>
          </box>
        </geometry>
        <surface>
          <contact>
            <collide_bitmask>255</collide_bitmask>
          </contact>
          <friction>
            <ode>
              <mu>1</mu>
              <mu2>1</mu2>
              <slip1>0</slip1>
              <slip2>0</slip2>
              <fdir1>0 0 0</fdir1>
            </ode>
          </friction>
        </surface>
      </collision>
      <collision name='collision_1'>
        <pose>0 0 0 0 0 0</pose>
        <geometry>
          <mesh>
            <uri>meshes/link_gripper_finger_right_1.obj</uri>
            <scale>0.90000000000000002 1 1</scale>
          </mesh>
        </geometry>
        <surface>
          <contact>
            <collide_bitmask>255</collide_bitmask>
          </contact>
          <friction>
            <ode>
              <mu>1</mu>
              <mu2>1</mu2>
              <slip1>0</slip1>
              <slip2>0</slip2>
              <fdir1>0 0 0</fdir1>
            </ode>
          </friction>
        </surface>
      </collision>
    </link>
    <link name='rubber_tip_right'>
      <pose relative_to='link_gripper_finger_right'>-0.171099 -0.014912 0 -1.5707963267948963 0 0</pose>
      <inertial>
        <pose>8.4448137139122313e-08 9.8008618023266253e-08 0.010368396070372586 -0.65828641506108876 -1.5707870621304898 -1.7057046808234502</pose>
        <mass>0.0050000000000000001</mass>
        <inertia>
          <ixx>7.8564728070097951e-07</ixx>
          <ixy>0</ixy>
          <ixz>0</ixz>
          <iyy>4.481050693166439e-07</iyy>
          <iyz>0</iyz>
          <izz>4.4808770717437325e-07</izz>
        </inertia>
      </inertial>
      <enable_wind>false</enable_wind>
      <collision name='collision_0'>
        <pose>0 0 0.012 0 0 0</pose>
        <geometry>
          <cylinder>
            <radius>0.02</radius>
            <length>0.01</length>
          </cylinder>
        </geometry>
        <surface>
          <contact>
            <collide_bitmask>255</collide_bitmask>
          </contact>
          <friction>
            <ode>
              <mu>0.80000000000000004</mu>
              <mu2>1</mu2>
              <slip1>0</slip1>
              <slip2>0</slip2>
              <fdir1>0 0 0</fdir1>
            </ode>
          </friction>
        </surface>
      </collision>
    </link>
    <link name='rubber_tip_right_dummy_0'>
      <pose relative_to='rubber_tip_right'>0 0 0 0 0 0</pose>
      <inertial>
        <pose>0 0 0 0 0 0</pose>
        <mass>9.9999999999999995e-07</mass>
        <inertia>
          <ixx>3.9999999999999998e-07</ixx>
          <ixy>0</ixy>
          <ixz>0</ixz>
          <iyy>3.9999999999999998e-07</iyy>
          <iyz>0</iyz>
          <izz>3.9999999999999998e-07</izz>
        </inertia>
      </inertial>
      <enable_wind>false</enable_wind>
    </link>
    <link name='link_head_pan'>
      <pose relative_to='base_link'>0.0061000200000000003 0 1.3552 0 0 0</pose>
      <inertial>
        <pose>-0.0003713599545455416 0.0086910005698150467 -0.0026943945594376881 0.41142254621105234 -0.09642115294447097 0.26286434308201029</pose>
        <mass>0.12737599999999999</mass>
        <inertia>
          <ixx>9.7042574014092738e-05</ixx>
          <ixy>0</ixy>
          <ixz>0</ixz>
          <iyy>9.6569011250629744e-05</iyy>
          <iyz>0</iyz>
          <izz>1.3444790805419728e-05</izz>
        </inertia>
      </inertial>
      <enable_wind>false</enable_wind>
      <collision name='collision_0'>
        <pose>0 0 0 0 0 0</pose>
        <geometry>
          <mesh>
            <uri>meshes/link_head_pan_0.obj</uri>
            <scale>1 1 1</scale>
          </mesh>
        </geometry>
        <surface>
          <contact>
            <collide_bitmask>255</collide_bitmask>
          </contact>
          <friction>
            <ode>
              <mu>1</mu>
              <mu2>1</mu2>
              <slip1>0</slip1>
              <slip2>0</slip2>
              <fdir1>0 0 0</fdir1>
            </ode>
          </friction>
        </surface>
      </collision>
      <collision name='collision_1'>
        <pose>0 0 0 0 0 0</pose>
        <geometry>
          <mesh>
            <uri>meshes/link_head_pan_1.obj</uri>
            <scale>1 1 1</scale>
          </mesh>
        </geometry>
        <surface>
          <contact>
            <collide_bitmask>255</collide_bitmask>
          </contact>
          <friction>
            <ode>
              <mu>1</mu>
              <mu2>1</mu2>
              <slip1>0</slip1>
              <slip2>0</slip2>
              <fdir1>0 0 0</fdir1>
            </ode>
          </friction>
        </surface>
      </collision>
    </link>
    <link name='link_head_tilt'>
      <pose relative_to='link_head_pan'>-0.0012999999999999999 0.027762499999999999 -0.053310799999999998 1.5707963267948963 0 0</pose>
      <inertial>
        <pose>0.015385630532244616 -0.025151191551339692 0.031573094259291584 -1.3766587296736967 -1.5408159849550693 2.9707116552161135</pose>
        <mass>0.26221699999999998</mass>
        <inertia>
          <ixx>0.00035830882521885787</ixx>
          <ixy>0</ixy>
          <ixz>0</ixz>
          <iyy>0.00033209648090074228</iyy>
          <iyz>0</iyz>
          <izz>0.0001736312881934397</izz>
        </inertia>
      </inertial>
      <enable_wind>false</enable_wind>
      <collision name='collision_0'>
        <pose>0 0 0 0 0 0</pose>
        <geometry>
          <mesh>
            <uri>meshes/link_head_tilt_0.obj</uri>
            <scale>1 1 1</scale>
          </mesh>
        </geometry>
        <surface>
          <contact>
            <collide_bitmask>255</collide_bitmask>
          </contact>
          <friction>
            <ode>
              <mu>1</mu>
              <mu2>1</mu2>
              <slip1>0</slip1>
              <slip2>0</slip2>
              <fdir1>0 0 0</fdir1>
            </ode>
          </friction>
        </surface>
      </collision>
      <collision name='collision_1'>
        <pose>0 0 0 0 0 0</pose>
        <geometry>
          <mesh>
            <uri>meshes/link_head_tilt_1.obj</uri>
            <scale>1 1 1</scale>
          </mesh>
        </geometry>
        <surface>
          <contact>
            <collide_bitmask>255</collide_bitmask>
          </contact>
          <friction>
            <ode>
              <mu>1</mu>
              <mu2>1</mu2>
              <slip1>0</slip1>
              <slip2>0</slip2>
              <fdir1>0 0 0</fdir1>
            </ode>
          </friction>
        </surface>
      </collision>
    </link>
    <link name='realsense'>
      <pose relative_to='link_head_tilt'>0.040599999999999997 0.0053 0.030700000000000002 0 0 0</pose>
      <inertial>
        <pose>0.040599999999999997 0.0053 0.030700000000000002 0 0 0</pose>
        <mass>0.1</mass>
        <inertia>
          <ixx>0.01</ixx>
          <ixy>0</ixy>
          <ixz>0</ixz>
          <iyy>0.01</iyy>
          <iyz>0</iyz>
          <izz>0.01</izz>
        </inertia>
      </inertial>
      <enable_wind>false</enable_wind>
      <sensor name='camera_rgb' type='camera'>
        <pose>0 0.014999999999999999 0 -3.1415926535897931 -2.4651903288156619e-32 2.2204460492503131e-16</pose>
        <topic>__default__</topic>
        <update_rate>25</update_rate>
        <enable_metrics>false</enable_metrics>
        <camera>
          <pose>0 0 0 0 0 0</pose>
          <horizontal_fov>1.0469999999999999</horizontal_fov>
          <image>
            <width>320</width>
            <height>240</height>
            <format>RGB_INT8</format>
            <anti_aliasing>4</anti_aliasing>
          </image>
          <camera_info_topic>__default__</camera_info_topic>
          <trigger_topic></trigger_topic>
          <triggered>false</triggered>
          <clip>
            <near>0.10000000000000001</near>
            <far>100</far>
          </clip>
          <save enabled='false'>
            <path>__default__</path>
          </save>
          <visibility_mask>4294967295</visibility_mask>
          <noise>
            <type>none</type>
            <mean>0</mean>
            <stddev>0</stddev>
          </noise>
          <distortion>
            <k1>0</k1>
            <k2>0</k2>
            <k3>0</k3>
            <p1>0</p1>
            <p2>0</p2>
            <center>0.5 0.5</center>
          </distortion>
          <lens>
            <type>stereographic</type>
            <scale_to_hfov>true</scale_to_hfov>
            <cutoff_angle>1.5707963267948966</cutoff_angle>
            <env_texture_size>256</env_texture_size>
          </lens>
          <optical_frame_id></optical_frame_id>
        </camera>
      </sensor>
      <sensor name='camera_depth' type='camera'>
        <pose>0 0 0 -3.1415926535897931 -2.4651903288156619e-32 2.2204460492503131e-16</pose>
        <topic>__default__</topic>
        <update_rate>25</update_rate>
        <enable_metrics>false</enable_metrics>
        <camera>
          <pose>0 0 0 0 0 0</pose>
          <horizontal_fov>1.0469999999999999</horizontal_fov>
          <image>
            <width>320</width>
            <height>240</height>
            <format>RGB_INT8</format>
            <anti_aliasing>4</anti_aliasing>
          </image>
          <camera_info_topic>__default__</camera_info_topic>
          <trigger_topic></trigger_topic>
          <triggered>false</triggered>
          <clip>
            <near>0.10000000000000001</near>
            <far>100</far>
          </clip>
          <save enabled='false'>
            <path>__default__</path>
          </save>
          <visibility_mask>4294967295</visibility_mask>
          <noise>
            <type>none</type>
            <mean>0</mean>
            <stddev>0</stddev>
          </noise>
          <distortion>
            <k1>0</k1>
            <k2>0</k2>
            <k3>0</k3>
            <p1>0</p1>
            <p2>0</p2>
            <center>0.5 0.5</center>
          </distortion>
          <lens>
            <type>stereographic</type>
            <scale_to_hfov>true</scale_to_hfov>
            <cutoff_angle>1.5707963267948966</cutoff_angle>
            <env_texture_size>256</env_texture_size>
          </lens>
          <optical_frame_id></optical_frame_id>
        </camera>
      </sensor>
    </link>
    <joint name='fixed_base_link_link_mast_joint' type='fixed'>
      <pose>0 0 0 0 0 0</pose>
      <parent>base_link</parent>
      <child>link_mast</child>
    </joint>
    <joint name='fixed_base_link_link_head_joint' type='fixed'>
      <pose>0 0 0 0 0 0</pose>
      <parent>base_link</parent>
      <child>link_head</child>
    </joint>
    <joint name='fixed_base_link_link_aruco_right_base_joint' type='fixed'>
      <pose>0 0 0 0 0 0</pose>
      <parent>base_link</parent>
      <child>link_aruco_right_base</child>
    </joint>
    <joint name='fixed_base_link_link_aruco_left_base_joint' type='fixed'>
      <pose>0 0 0 0 0 0</pose>
      <parent>base_link</parent>
      <child>link_aruco_left_base</child>
    </joint>
    <joint name='fixed_base_link_laser_joint' type='fixed'>
      <pose>0 0 0 0 0 0</pose>
      <parent>base_link</parent>
      <child>laser</child>
    </joint>
    <joint name='joint_joint_right_wheel' type='revolute'>
      <pose>0 0 0 0 0 0</pose>
      <parent>base_link</parent>
      <child>link_right_wheel</child>
      <axis>
        <xyz>0 0 -1</xyz>
        <limit>
          <lower>-inf</lower>
          <upper>inf</upper>
          <effort>inf</effort>
          <velocity>inf</velocity>
          <stiffness>100000000</stiffness>
          <dissipation>1</dissipation>
        </limit>
        <dynamics>
          <spring_reference>0</spring_reference>
          <spring_stiffness>0</spring_stiffness>
          <damping>0.29999999999999999</damping>
          <friction>0</friction>
        </dynamics>
      </axis>
    </joint>
    <joint name='joint_joint_left_wheel' type='revolute'>
      <pose>0 0 0 0 0 0</pose>
      <parent>base_link</parent>
      <child>link_left_wheel</child>
      <axis>
        <xyz>0 0 -1</xyz>
        <limit>
          <lower>-inf</lower>
          <upper>inf</upper>
          <effort>inf</effort>
          <velocity>inf</velocity>
          <stiffness>100000000</stiffness>
          <dissipation>1</dissipation>
        </limit>
        <dynamics>
          <spring_reference>0</spring_reference>
          <spring_stiffness>0</spring_stiffness>
          <damping>0.29999999999999999</damping>
          <friction>0</friction>
        </dynamics>
      </axis>
    </joint>
    <joint name='joint_joint_lift' type='prismatic'>
      <pose>0 0 0 0 0 0</pose>
      <parent>base_link</parent>
      <child>link_lift</child>
      <axis>
        <xyz>0 0 1</xyz>
        <limit>
          <lower>-inf</lower>
          <upper>inf</upper>
          <effort>inf</effort>
          <velocity>inf</velocity>
          <stiffness>100000000</stiffness>
          <dissipation>1</dissipation>
        </limit>
        <dynamics>
          <spring_reference>0</spring_reference>
          <spring_stiffness>0</spring_stiffness>
          <damping>5</damping>
          <friction>0</friction>
        </dynamics>
      </axis>
    </joint>
    <joint name='fixed_link_lift_link_arm_l4_joint' type='fixed'>
      <pose>0 0 0 0 0 0</pose>
      <parent>link_lift</parent>
      <child>link_arm_l4</child>
    </joint>
    <joint name='joint_joint_arm_l3' type='prismatic'>
      <pose>0 0 0 0 0 0</pose>
      <parent>link_arm_l4</parent>
      <child>link_arm_l3</child>
      <axis>
        <xyz>0 0 1</xyz>
        <limit>
          <lower>-inf</lower>
          <upper>inf</upper>
          <effort>inf</effort>
          <velocity>inf</velocity>
          <stiffness>100000000</stiffness>
          <dissipation>1</dissipation>
        </limit>
        <dynamics>
          <spring_reference>0</spring_reference>
          <spring_stiffness>0</spring_stiffness>
          <damping>5</damping>
          <friction>0</friction>
        </dynamics>
      </axis>
    </joint>
    <joint name='joint_joint_arm_l2' type='prismatic'>
      <pose>0 0 0 0 0 0</pose>
      <parent>link_arm_l3</parent>
      <child>link_arm_l2</child>
      <axis>
        <xyz>0 0 1</xyz>
        <limit>
          <lower>-inf</lower>
          <upper>inf</upper>
          <effort>inf</effort>
          <velocity>inf</velocity>
          <stiffness>100000000</stiffness>
          <dissipation>1</dissipation>
        </limit>
        <dynamics>
          <spring_reference>0</spring_reference>
          <spring_stiffness>0</spring_stiffness>
          <damping>5</damping>
          <friction>0</friction>
        </dynamics>
      </axis>
    </joint>
    <joint name='joint_joint_arm_l1' type='prismatic'>
      <pose>0 0 0 0 0 0</pose>
      <parent>link_arm_l2</parent>
      <child>link_arm_l1</child>
      <axis>
        <xyz>0 0 1</xyz>
        <limit>
          <lower>-inf</lower>
          <upper>inf</upper>
          <effort>inf</effort>
          <velocity>inf</velocity>
          <stiffness>100000000</stiffness>
          <dissipation>1</dissipation>
        </limit>
        <dynamics>
          <spring_reference>0</spring_reference>
          <spring_stiffness>0</spring_stiffness>
          <damping>5</damping>
          <friction>0</friction>
        </dynamics>
      </axis>
    </joint>
    <joint name='joint_joint_arm_l0' type='prismatic'>
      <pose>0 0 0 0 0 0</pose>
      <parent>link_arm_l1</parent>
      <child>link_arm_l0</child>
      <axis>
        <xyz>0 0 1</xyz>
        <limit>
          <lower>-inf</lower>
          <upper>inf</upper>
          <effort>inf</effort>
          <velocity>inf</velocity>
          <stiffness>100000000</stiffness>
          <dissipation>1</dissipation>
        </limit>
        <dynamics>
          <spring_reference>0</spring_reference>
          <spring_stiffness>0</spring_stiffness>
          <damping>5</damping>
          <friction>0</friction>
        </dynamics>
      </axis>
    </joint>
    <joint name='fixed_link_arm_l0_link_aruco_top_wrist_joint' type='fixed'>
      <pose>0 0 0 0 0 0</pose>
      <parent>link_arm_l0</parent>
      <child>link_aruco_top_wrist</child>
    </joint>
    <joint name='fixed_link_arm_l0_link_aruco_inner_wrist_joint' type='fixed'>
      <pose>0 0 0 0 0 0</pose>
      <parent>link_arm_l0</parent>
      <child>link_aruco_inner_wrist</child>
    </joint>
    <joint name='joint_joint_wrist_yaw' type='revolute'>
      <pose>0 0 0 0 0 0</pose>
      <parent>link_arm_l0</parent>
      <child>link_wrist_yaw</child>
      <axis>
        <xyz>0 0 -1</xyz>
        <limit>
          <lower>-inf</lower>
          <upper>inf</upper>
          <effort>inf</effort>
          <velocity>inf</velocity>
          <stiffness>100000000</stiffness>
          <dissipation>1</dissipation>
        </limit>
        <dynamics>
          <spring_reference>0</spring_reference>
          <spring_stiffness>0</spring_stiffness>
          <damping>0.10000000000000001</damping>
          <friction>0</friction>
        </dynamics>
      </axis>
    </joint>
    <joint name='joint_joint_gripper_slide' type='prismatic'>
      <pose>0 0 0 0 0 0</pose>
      <parent>link_wrist_yaw</parent>
      <child>link_gripper_slider</child>
      <axis>
        <xyz>1 0 0</xyz>
        <limit>
          <lower>-inf</lower>
          <upper>inf</upper>
          <effort>inf</effort>
          <velocity>inf</velocity>
          <stiffness>100000000</stiffness>
          <dissipation>1</dissipation>
        </limit>
        <dynamics>
          <spring_reference>0</spring_reference>
          <spring_stiffness>0</spring_stiffness>
          <damping>0.10000000000000001</damping>
          <friction>0</friction>
        </dynamics>
      </axis>
    </joint>
    <joint name='joint_joint_gripper_finger_left_open' type='revolute'>
      <pose>0 0 0 0 0 0</pose>
      <parent>link_gripper_slider</parent>
      <child>link_gripper_finger_left</child>
      <axis>
        <xyz>0 0 1</xyz>
        <limit>
          <lower>-inf</lower>
          <upper>inf</upper>
          <effort>inf</effort>
          <velocity>inf</velocity>
          <stiffness>100000000</stiffness>
          <dissipation>1</dissipation>
        </limit>
        <dynamics>
          <spring_reference>0</spring_reference>
          <spring_stiffness>0</spring_stiffness>
          <damping>0.10000000000000001</damping>
          <friction>0</friction>
        </dynamics>
      </axis>
    </joint>
    <joint name='joint_rubber_left_x' type='revolute'>
      <pose>0 0 0 0 0 0</pose>
      <parent>link_gripper_finger_left</parent>
      <child>rubber_tip_left_dummy_0</child>
      <axis>
        <xyz>1 0 0</xyz>
        <limit>
          <lower>-inf</lower>
          <upper>inf</upper>
          <effort>inf</effort>
          <velocity>inf</velocity>
          <stiffness>100000000</stiffness>
          <dissipation>1</dissipation>
        </limit>
        <dynamics>
          <spring_reference>0</spring_reference>
          <spring_stiffness>0.050000000000000003</spring_stiffness>
          <damping>0.001</damping>
          <friction>0</friction>
        </dynamics>
      </axis>
    </joint>
    <joint name='joint_rubber_left_y' type='revolute'>
      <pose>0 0 0 0 0 0</pose>
      <parent>rubber_tip_left_dummy_0</parent>
      <child>rubber_tip_left</child>
      <axis>
        <xyz>0 1 0</xyz>
        <limit>
          <lower>-inf</lower>
          <upper>inf</upper>
          <effort>inf</effort>
          <velocity>inf</velocity>
          <stiffness>100000000</stiffness>
          <dissipation>1</dissipation>
        </limit>
        <dynamics>
          <spring_reference>0</spring_reference>
          <spring_stiffness>0.050000000000000003</spring_stiffness>
          <damping>0.001</damping>
          <friction>0</friction>
        </dynamics>
      </axis>
    </joint>
    <joint name='joint_joint_gripper_finger_right_open' type='revolute'>
      <pose>0 0 0 0 0 0</pose>
      <parent>link_gripper_slider</parent>
      <child>link_gripper_finger_right</child>
      <axis>
        <xyz>0 0 1</xyz>
        <limit>
          <lower>-inf</lower>
          <upper>inf</upper>
          <effort>inf</effort>
          <velocity>inf</velocity>
          <stiffness>100000000</stiffness>
          <dissipation>1</dissipation>
        </limit>
        <dynamics>
          <spring_reference>0</spring_reference>
          <spring_stiffness>0</spring_stiffness>
          <damping>0.10000000000000001</damping>
          <friction>0</friction>
        </dynamics>
      </axis>
    </joint>
    <joint name='joint_rubber_right_x' type='revolute'>
      <pose>0 0 0 0 0 0</pose>
      <parent>link_gripper_finger_right</parent>
      <child>rubber_tip_right_dummy_0</child>
      <axis>
        <xyz>1 0 0</xyz>
        <limit>
          <lower>-inf</lower>
          <upper>inf</upper>
          <effort>inf</effort>
          <velocity>inf</velocity>
          <stiffness>100000000</stiffness>
          <dissipation>1</dissipation>
        </limit>
        <dynamics>
          <spring_reference>0</spring_reference>
          <spring_stiffness>0.050000000000000003</spring_stiffness>
          <damping>0.001</damping>
          <friction>0</friction>
        </dynamics>
      </axis>
    </joint>
    <joint name='joint_rubber_right_y' type='revolute'>
      <pose>0 0 0 0 0 0</pose>
      <parent>rubber_tip_right_dummy_0</parent>
      <child>rubber_tip_right</child>
      <axis>
        <xyz>0 1 0</xyz>
        <limit>
          <lower>-inf</lower>
          <upper>inf</upper>
          <effort>inf</effort>
          <velocity>inf</velocity>
          <stiffness>100000000</stiffness>
          <dissipation>1</dissipation>
        </limit>
        <dynamics>
          <spring_reference>0</spring_reference>
          <spring_stiffness>0.050000000000000003</spring_stiffness>
          <damping>0.001</damping>
          <friction>0</friction>
        </dynamics>
      </axis>
    </joint>
    <joint name='joint_joint_head_pan' type='revolute'>
      <pose>0 0 0 0 0 0</pose>
      <parent>base_link</parent>
      <child>link_head_pan</child>
      <axis>
        <xyz>0 0 1</xyz>
        <limit>
          <lower>-inf</lower>
          <upper>inf</upper>
          <effort>inf</effort>
          <velocity>inf</velocity>
          <stiffness>100000000</stiffness>
          <dissipation>1</dissipation>
        </limit>
        <dynamics>
          <spring_reference>0</spring_reference>
          <spring_stiffness>0</spring_stiffness>
          <damping>1</damping>
          <friction>0</friction>
        </dynamics>
      </axis>
    </joint>
    <joint name='joint_joint_head_tilt' type='revolute'>
      <pose>0 0 0 0 0 0</pose>
      <parent>link_head_pan</parent>
      <child>link_head_tilt</child>
      <axis>
        <xyz>0 0 1</xyz>
        <limit>
          <lower>-inf</lower>
          <upper>inf</upper>
          <effort>inf</effort>
          <velocity>inf</velocity>
          <stiffness>100000000</stiffness>
          <dissipation>1</dissipation>
        </limit>
        <dynamics>
          <spring_reference>0</spring_reference>
          <spring_stiffness>0</spring_stiffness>
          <damping>1</damping>
          <friction>0</friction>
        </dynamics>
      </axis>
    </joint>
    <joint name='fixed_link_head_tilt_realsense_joint' type='fixed'>
      <pose>0 0 0 0 0 0</pose>
      <parent>link_head_tilt</parent>
      <child>realsense</child>
    </joint>
  </model>
</sdf>
